Workbook

Sheet 起源
A1: 人物背景 Background
B3: 角色名 | O3: 背景获利 | AP3: 背景描述
B4: 玩家 | O4: 属性值 | S4: =背景!J2 -> 见注释，或自选至多三项 | AB4: 专长 | AF4: =背景!K2 -> 自选一项起源专长 | AP4: =背景!O2 -> 角色的背景代表了这个角色在成为冒险者之前的经历。通过创建一个独特的背景或对玩家手册中现有的背景进行修改，你可以反映战役的特定主题或是你世界中的独特元素。你也可以通过创建新的背景来帮助玩家为他们的角色制作心目中的起源故事。
B5: 故乡 | O5: 技能熟练 | S5: =背景!L2 -> 自选两个适合背景的技能
B6: 背景 | E6: 工匠 | O6: 工具熟练 | S6: =背景!M2 -> 选择一个工具，它与该背景有关，或是经常被该背景的人使用
O7: 背景装备 | S7: =背景!N2 -> 组合一套价值50GP的装备（购买完毕后多余的钱也会包含在其内）。不要将包含军用武器和护甲包含在背景给予的装备中，角色会从其职业中获得这两样装备。
B8: 年龄 | H8: 身高
B9: 性别 | H9: 体重
B11: 人物形象 | O11: 个性 | AV11: 人物立绘
O13: 理念
O14: 羁绊
O15: 缺陷
O17: 背景故事
B23: 语言
B30: 熟练工具
B31: 选择一种工匠工具（参见第六章）

Sheet 主要
A1: DND 5.5E 人物卡<悲灵ver.>（2024） | AV1: =".st"& " 力量"&IF($B$13="O","*","")&":"&$F$13& " 敏捷"&IF($B$14="O","*","")&":"&$F$14& " 体质"&IF($B$15="O","*","")&":"&$F$15& " 智力"&IF($B$16="O","*","")&":"&$F$16& " 感知"&IF($B$17="O","*","")&":"&$F$17& " 魅力"&IF($B$18="O","*","")&":"&$F$18& " hp"&":"&R22&" hpmax"&":"&V22& " 先攻"&":"&D22&" ac"&":"&D23&" dc"&":"&D24&" pp"&":"&$L$23&" 熟练"&":"&S3& " 运动"&IF($B$41="O","*",IF($B$41="🅞","*2",IF($H$39="O","*0.5","")))&":"&IF($F$41+$X$11="",0,$F$41+$X$11)& " 特技"&IF($B$43="O","*",IF($B$43="🅞","*2",IF($H$39="O","*0.5","")))&":"&IF($F$43+$X$11="",0,$F$43+$X$11)& " 巧手"&IF($B$44="O","*",IF($B$44="🅞","*2",IF($H$39="O","*0.5","")))&":"&IF($F$44+$X$11="",0,$F$44+$X$11)& " 隐匿"&IF($B$45="O","*",IF($B$45="🅞","*2",IF($H$39="O","*0.5","")))&":"&IF($F$45+$X$11="",0,$F$45+$X$11)& " 调查"&IF($B$47="O","*",IF($B$47="🅞","*2",IF($H$39="O","*0.5","")))&":"&IF($F$47+$X$11="",0,$F$47+$X$11)& " 奥秘"&IF($B$48="O","*",IF($B$48="🅞","*2",IF($H$39="O","*0.5","")))&":"&IF($F$48+$X$11="",0,$F$48+$X$11)& " 历史"&IF($B$49="O","*",IF($B$49="🅞","*2",IF($H$39="O","*0.5","")))&":"&IF($F$49+$X$11="",0,$F$49+$X$11)& " 自然"&IF($B$50="O","*",IF($B$50="🅞","*2",IF($H$39="O","*0.5","")))&":"&IF($F$50+$X$11="",0,$F$50+$X$11)& " 宗教"&IF($B$51="O","*",IF($B$51="🅞","*2",IF($H$39="O","*0.5","")))&":"&IF($F$51+$X$11="",0,$F$51+$X$11)& " 察觉"&IF($B$53="O","*",IF($B$53="🅞","*2",IF($H$39="O","*0.5","")))&":"&IF($F$53+$X$11="",0,$F$53+$X$11)& " 洞悉"&IF($B$54="O","*",IF($B$54="🅞","*2",IF($H$39="O","*0.5","")))&":"&IF($F$54+$X$11="",0,$F$54+$X$11)& " 驯兽"&IF($B$55="O","*",IF($B$55="🅞","*2",IF($H$39="O","*0.5","")))&":"&IF($F$55+$X$11="",0,$F$55+$X$11)& " 医疗"&IF($B$56="O","*",IF($B$56="🅞","*2",IF($H$39="O","*0.5","")))&":"&IF($F$56+$X$11="",0,$F$56+$X$11)& " 求生"&IF($B$57="O","*",IF($B$57="🅞","*2",IF($H$39="O","*0.5","")))&":"&IF($F$57+$X$11="",0,$F$57+$X$11)& " 游说"&IF($B$59="O","*",IF($B$59="🅞","*2",IF($H$39="O","*0.5","")))&":"&IF($F$59+$X$11="",0,$F$59+$X$11)& " 欺瞒"&IF($B$60="O","*",IF($B$60="🅞","*2",IF($H$39="O","*0.5","")))&":"&IF($F$60+$X$11="",0,$F$60+$X$11)& " 威吓"&IF($B$61="O","*",IF($B$61="🅞","*2",IF($H$39="O","*0.5","")))&":"&IF($F$61+$X$11="",0,$F$61+$X$11)& " 表演"&IF($B$62="O","*",IF($B$62="🅞","*2",IF($H$39="O","*0.5","")))&":"&IF($F$62+$X$11="",0,$F$62+$X$11) -> .st 力量:10 敏捷:10 体质:10 智力:10 感知:10 魅力:10 hp:0 hpmax:0 先攻:0 ac:10 dc:10 pp:10 熟练:2 运动:0 特技:0 巧手:0 隐匿:0 调查:0 奥秘:0 历史:0 自然:0 宗教:0 察觉:0 洞悉:0 驯兽:0 医疗:0 求生:0 游说:0 欺瞒:0 威吓:0 表演:0 | AW1: 生命值小工具 | BJ1: 生命骰使用期望 | BQ1: 是 | BT1: 种族特性
AX2: 1级 | AZ2: 2级 | BB2: 3级 | BD2: 4级 | BF2: 5级 | BH2: 6级 | BJ2: 7级 | BL2: 8级 | BN2: 9级 | BP2: 10级 | BT2: 名称 | BZ2: 描述
B3: 角色名 | E3: 琼脂糖 | Q3: 熟练 | S3: =IFERROR(VLOOKUP(SUM(O6,O7,O8),数据表!CM2:CN21,2,FALSE)+W4,IF(SUM(O6,O7,O8)>=20,6,2)) -> 2 | W3: 修正 | AW3: 生命值小工具 | BT3: 生物种类
B4: 玩家 | E4: 悲灵 | V4: < | AX4: 11级 | AZ4: 12级 | BB4: 13级 | BD4: 14级 | BF4: 15级 | BH4: 16级 | BJ4: 17级 | BL4: 18级 | BN4: 19级 | BP4: 20级 | BT4: 体型
E5: 主职 | I5: 子职 | O5: Lv | BT5: 速度
B6: 主职业 | E6: 野蛮人 | I6: 狂战士道途 | O6: 8 | R6: 种族 | T6: 半身人 | AX6: 额外调整值 | BB6: 修正 | BF6: 生命总值 | BI6: 仅需填入每级生命骰结果 自动结算等级与体质调整值 | BT6: 勇气
B7: 兼职1 | R7: 亚种 | BF7: =IF(BQ1="否",SUM(AX3:BQ3,AX5:BQ5,(R15+AX7)*(O6+O7+O8),BB7), SUM(O6*职业!AT2,O7*职业!AT3,O8*职业!AT4,职业!AT7,(R15+AX7)*(O6+O7+O8),BB7)) -> 0 | BT7: 半身人灵巧
B8: 兼职2 | R8: 阵营 | T8: 守序善良 | BT8: 天生善匿
B9: 经验值 | O9: =IF(E9="","","Lv "&VLOOKUP(E9,数据表!CI3:CJ22,2,TRUE)) | R9: 信仰 | BJ9: 职业能力 | BT9: 幸运
AW10: Lv | AX10: 名称 | BC10: 描述
B11: 属性 | R11: 全局检定修正 | AW11: =职业!CV2 | AX11: 豁免熟练
B12: 熟练 | F12: 总值 | H12: 初始值 | K12: 背景 | M12: 成长 | O12: 修正 | Q12: 调整值 | T12: 豁免 | W12: 修正 | AW12: =职业!CV3 | AX12: 技能熟练
B13: X | C13: 力量 | F13: =I13+K13+M13+O13 -> 10 | H13: < | I13: 10 | Q13: > | R13: =INT(F13/2-5) -> 0 | T13: =INT(F13/2-5)+IF(B13="O",$S$3,0)+W13 -> 0 | V13: < | AW13: =职业!CV4 | AX13: 武器熟练
B14: X | C14: 敏捷 | F14: =I14+K14+M14+O14 -> 10 | H14: < | I14: 10 | Q14: > | R14: =INT(F14/2-5) -> 0 | T14: =INT(F14/2-5)+IF(B14="O",$S$3,0)+W14 -> 0 | V14: < | AW14: =职业!CV5 | AX14: 工具熟练
B15: X | C15: 体质 | F15: =I15+K15+M15+O15 -> 10 | H15: < | I15: 10 | Q15: > | R15: =INT(F15/2-5) -> 0 | T15: =INT(F15/2-5)+IF(B15="O",$S$3,0)+W15 -> 0 | V15: < | AW15: =职业!CV6 | AX15: 护甲受训
B16: X | C16: 智力 | F16: =I16+K16+M16+O16 -> 10 | H16: < | I16: 10 | Q16: > | R16: =INT(F16/2-5) -> 0 | T16: =INT(F16/2-5)+IF(B16="O",$S$3,0)+W16 -> 0 | V16: < | AW16: =职业!CV7 | AX16: 起始装备
B17: X | C17: 感知 | F17: =I17+K17+M17+O17 -> 10 | H17: < | I17: 10 | Q17: > | R17: =INT(F17/2-5) -> 0 | T17: =INT(F17/2-5)+IF(B17="O",$S$3,0)+W17 -> 0 | V17: < | AW17: =职业!CV8 | BT17: 专长
B18: X | C18: 魅力 | F18: =I18+K18+M18+O18 -> 10 | H18: < | I18: 10 | Q18: > | R18: =INT(F18/2-5) -> 0 | T18: =INT(F18/2-5)+IF(B18="O",$S$3,0)+W18 -> 0 | V18: < | AW18: =职业!CV9 | BT18: Lv | BU18: 名称 | BZ18: 描述
AW19: =职业!CV10 | BT19: 1 | BU19: 专注重击
B20: 战斗 | R20: 持有英雄激励 | X20: 否 | AW20: =职业!CV11 | BT20: 4 | BU20: 云端漫步者
G21: 修正 | S21: Now | V21: Max | AA21: 画像 | AW21: =职业!CV12 | BT21: 8 | BU21: 巧匠
B22: 先攻 | D22: =SUM(R14+G22) -> 0 | F22: < | P22: HP | R22: =V22 -> 0 | U22: / | V22: =BF7 -> 0 | AA22: 抗性 | AO22: 黑视 | AW22: =职业!CV13 | BT22: 12
B23: AC | D23: =SUM(AF40,AI40,G23,+IF(AS40="是",AQ40,0)) -> 10 | F23: < | J23: 被察 | L23: =SUM(10+I53) -> 10 | P23: HD | R23: =U23 -> 1 | T23: / | U23: =O6+O7+O8 -> 1 | W23: =IF(E7="",IF(E8="",IFERROR(VLOOKUP(E6,职业!AO2:AP21,2,0),""),""),"") | AA23: 免疫 | AO23: 体型 | AR23: 中型 | AW23: =职业!CV14 | BT23: 16
B24: DC | D24: =SUM(8+S3+G24+VLOOKUP(L24,C13:S18,16,FALSE)) -> 10 | F24: < | I24: < | J24: 属性 | L24: 魅力 | P24: 临时生命 | AA24: 优势 | AO24: 速度 | AR24: 30 | AW24: =职业!CV15 | BT24: 19
B25: 名称 | F25: 描述 | J25: Now | M25: Max | O25: 回复 | Q25: 名称 | U25: 描述 | Y25: Now | AB25: Max | AD25: 回复 | AF25: 名称 | AJ25: 描述 | AN25: Now | AQ25: Max | AS25: 回复 | AW25: =职业!CV16 | BT25: 6
B26: 特殊能力 | L26: / | Q26: 特殊能力 | AA26: / | AF26: 特殊能力 | AP26: / | AW26: =职业!CV17 | BT26: 10
B27: 特殊能力 | L27: / | Q27: 特殊能力 | AA27: / | AF27: 特殊能力 | AP27: / | AW27: =职业!CV18
B28: 特殊能力 | L28: / | Q28: 特殊能力 | AA28: / | AF28: 特殊能力 | AP28: / | AW28: =职业!CV19
AW29: =职业!CV20
B30: 武器 | U30: 攻击属性 | AA30: 默认 | AE30: 弹药 | AK30: 箭矢 | AP30: 数量 | AS30: 0 | AW30: =职业!CV21
B31: 武器类型 | F31: 同调 | H31: 名称 | L31: 加值 | N31: 特性 | W31: 熟练 | X31: 攻击骰 | AB31: 伤害骰 | AF31: 类型 | AH31: 附加伤害骰 | AL31: 类型 | AN31: 精通 | AP31: 效果 | AW31: =职业!CV22 | BT31: 战斗风格专长
G32: > | M32: =装备!AS2 | V32: > | W32: O | X32: D20 | Z32: =装备!AU2 | AB32: =装备!AQ2 | AD32: =IF(装备!AW2="","",IF(装备!AZ2=1,"",IF(装备!AW2>=0,CONCATENATE("+",装备!AW2),装备!AW2))) | AF32: =装备!AR2 | AN32: =装备!AT2 | AP32: =装备!AC2 | AW32: =职业!CV23 | BT32: 名称 | BZ32: 描述
G33: > | M33: =装备!AS3 | V33: > | W33: O | X33: D20 | Z33: =装备!AU3 | AB33: =装备!AQ3 | AD33: =IF(装备!AW3="","",IF(装备!AZ3=1,"",IF(装备!AW3>=0,CONCATENATE("+",装备!AW3),装备!AW3))) | AF33: =装备!AR3 | AN33: =装备!AT3 | AP33: =装备!AC3 | AW33: =职业!CV24
G34: > | M34: =装备!AS4 | V34: > | W34: O | X34: D20 | Z34: =装备!AU4 | AB34: =装备!AQ4 | AD34: =IF(装备!AW4="","",IF(装备!AZ4=1,"",IF(装备!AW4>=0,CONCATENATE("+",装备!AW4),装备!AW4))) | AF34: =装备!AR4 | AN34: =装备!AT4 | AP34: =装备!AC4 | AW34: =职业!CV25
G35: > | M35: =装备!AS5 | V35: > | W35: O | X35: D20 | Z35: =装备!AU5 | AB35: =装备!AQ5 | AD35: =IF(装备!AW5="","",IF(装备!AZ5=1,"",IF(装备!AW5>=0,CONCATENATE("+",装备!AW5),装备!AW5))) | AF35: =装备!AR5 | AN35: =装备!AT5 | AP35: =装备!AC5 | AW35: =职业!CV26
G36: > | M36: =装备!AS6 | V36: > | W36: O | X36: D20 | Z36: =装备!AU6 | AB36: =装备!AQ6 | AD36: =IF(装备!AW6="","",IF(装备!AZ6=1,"",IF(装备!AW6>=0,CONCATENATE("+",装备!AW6),装备!AW6))) | AF36: =装备!AR6 | AN36: =装备!AT6 | AP36: =装备!AC6 | AW36: =职业!CV27
AW37: =职业!CV28
B38: 技能 | L38: 装备 | AM38: 已同调的装备 | AS38: =SUM(装备!T20:T36) -> 0 | AW38: =职业!CV29 | BT38: 特殊能力
B39: 万事通 | H39: X | L39: 护甲类型 | P39: 同调 | R39: 名称 | U39: 加值 | V39: 特性 | AF39: AC | AH39: 敏捷加值 | AL39: 盾牌 | AP39: 同调 | AQ39: AC | AS39: 着装 | AW39: =职业!CV30 | BT39: 名称 | BZ39: 描述
B40: 熟练 | D40: 力量 | F40: 修正 | I40: 总值 | V40: =装备!AY12 | AE40: > | AF40: =装备!AV12+U40 -> 10 | AH40: + | AI40: =装备!AW12 -> 0 | AQ40: 2 | AS40: 否 | AW40: =职业!CV31
...

Sheet 数据表
B1: 法术书 | C1: 专注 | D1: 仪式 | E1: 准备栏 | I1: 仪 | J1: 专 | K1: {=IFERROR(INDEX($H$1:$H$68,SMALL(IF($H$2:$H$68<>"",ROW($H$2:$H$68),4^8),ROW(1:1)))&"","")} | M1: 语言 | P1: 1 | Q1: 2 | R1: 3 | S1: 4 | T1: 5 | U1: 6 | V1: 7 | W1: 8 | X1: 9 | Y1: 10 | Z1: 11 | AA1: 12 | AB1: 13 | AC1: 14 | AD1: 15 | AE1: 16 | AF1: 17 | AG1: 18 | AH1: 19 | AI1: 20 | AJ1: 等级 | CI1: 经验值 | CM1: 等级 | CN1: 熟练加值 | CO1: CR | CP1: 熟练加值
A2: 1 | B2: =IF(法术书!X3="","",法术书!X3) | C2: =IFERROR(VLOOKUP(B2,法术大全!$A:$W,5,FALSE),"") | D2: =IFERROR(VLOOKUP(B2,法术大全!$A:$W,4,FALSE),"") | E2: 1 | F2: {=IFERROR(INDEX($B$1:$B$301,SMALL(IF($B$1:$B$301<>"",ROW($B$1:$B$301),4^8),ROW(2:2)))&"","")} | G2: 无消耗 | H2: =IF(主要!Q66<>"",主要!Q66,"") | I2: =IF(VLOOKUP(H2,法术大全!$A$3:$E$864,4,0)="√",1,0) -> 0 | J2: =IF(VLOOKUP(H2,法术大全!$A$3:$E$864,5,0)="√",1,0) -> 0 | K2: {=IFERROR(INDEX($H$1:$H$68,SMALL(IF($H$2:$H$68<>"",ROW($H$2:$H$68),4^8),ROW(2:2)))&"","")} | M2: —标准语言— | O2: 吟游诗人 | P2: 4 | Q2: 5 | R2: 6 | S2: 7 | T2: 9 | U2: 10 | V2: 11 | W2: 12 | X2: 14 | Y2: 15 | Z2: 16 | AA2: 16 | AB2: 17 | AC2: 17 | AD2: 18 | AE2: 18 | AF2: 19 | AG2: 20 | AH2: 21 | AI2: 22 | AJ2: =职业!$AZ$3 -> 0 | AL2: 笔记 | BP2: 笔记 | CI2: Exp | CJ2: Lv | CK2: 戏法 | CL2: 0 | CM2: 1 | CN2: 2 | CO2: 0 | CP2: 2
A3: 2 | B3: =IF(法术书!X4="","",法术书!X4) | C3: =IFERROR(VLOOKUP(B3,法术大全!$A:$W,5,FALSE),"") | D3: =IFERROR(VLOOKUP(B3,法术大全!$A:$W,4,FALSE),"") | E3: 2 | F3: {=IFERROR(INDEX($B$1:$B$301,SMALL(IF($B$1:$B$301<>"",ROW($B$1:$B$301),4^8),ROW(3:3)))&"","")} | H3: =IF(主要!Q67<>"",主要!Q67,"") | I3: =IF(VLOOKUP(H3,法术大全!$A$3:$E$864,4,0)="√",1,0) -> 0 | J3: =IF(VLOOKUP(H3,法术大全!$A$3:$E$864,5,0)="√",1,0) -> 0 | K3: {=IFERROR(INDEX($H$1:$H$68,SMALL(IF($H$2:$H$68<>"",ROW($H$2:$H$68),4^8),ROW(3:3)))&"","")} | M3: 通用语 | O3: 牧师 | P3: 4 | Q3: 5 | R3: 6 | S3: 7 | T3: 9 | U3: 10 | V3: 11 | W3: 12 | X3: 14 | Y3: 15 | Z3: 16 | AA3: 16 | AB3: 17 | AC3: 17 | AD3: 18 | AE3: 18 | AF3: 19 | AG3: 20 | AH3: 21 | AI3: 22 | AJ3: =职业!$AZ$4 -> 0 | CI3: 0 | CJ3: 1 | CK3: 1环 | CL3: 1 | CM3: 2 | CN3: 2 | CO3: 1/8 | CP3: 2
A4: 3 | B4: =IF(法术书!X5="","",法术书!X5) | C4: =IFERROR(VLOOKUP(B4,法术大全!$A:$W,5,FALSE),"") | D4: =IFERROR(VLOOKUP(B4,法术大全!$A:$W,4,FALSE),"") | E4: 3 | F4: {=IFERROR(INDEX($B$1:$B$301,SMALL(IF($B$1:$B$301<>"",ROW($B$1:$B$301),4^8),ROW(4:4)))&"","")} | H4: =IF(主要!Q68<>"",主要!Q68,"") | I4: =IF(VLOOKUP(H4,法术大全!$A$3:$E$864,4,0)="√",1,0) -> 0 | J4: =IF(VLOOKUP(H4,法术大全!$A$3:$E$864,5,0)="√",1,0) -> 0 | K4: {=IFERROR(INDEX($H$1:$H$68,SMALL(IF($H$2:$H$68<>"",ROW($H$2:$H$68),4^8),ROW(4:4)))&"","")} | M4: 通用手语 | O4: 德鲁伊 | P4: 4 | Q4: 5 | R4: 6 | S4: 7 | T4: 9 | U4: 10 | V4: 11 | W4: 12 | X4: 14 | Y4: 15 | Z4: 16 | AA4: 16 | AB4: 17 | AC4: 17 | AD4: 18 | AE4: 18 | AF4: 19 | AG4: 20 | AH4: 21 | AI4: 22 | AJ4: =职业!$AZ$5 -> 0 | CI4: 300 | CJ4: 2 | CK4: 2环 | CL4: 2 | CM4: 3 | CN4: 2 | CO4: 1/4 | CP4: 2
A5: 4 | B5: =IF(法术书!X6="","",法术书!X6) | C5: =IFERROR(VLOOKUP(B5,法术大全!$A:$W,5,FALSE),"") | D5: =IFERROR(VLOOKUP(B5,法术大全!$A:$W,4,FALSE),"") | E5: 4 | F5: {=IFERROR(INDEX($B$1:$B$301,SMALL(IF($B$1:$B$301<>"",ROW($B$1:$B$301),4^8),ROW(5:5)))&"","")} | H5: =IF(主要!Q69<>"",主要!Q69,"") | I5: =IF(VLOOKUP(H5,法术大全!$A$3:$E$864,4,0)="√",1,0) -> 0 | J5: =IF(VLOOKUP(H5,法术大全!$A$3:$E$864,5,0)="√",1,0) -> 0 | K5: {=IFERROR(INDEX($H$1:$H$68,SMALL(IF($H$2:$H$68<>"",ROW($H$2:$H$68),4^8),ROW(5:5)))&"","")} | M5: 龙语 | O5: 圣武士 | P5: 2 | Q5: 3 | R5: 4 | S5: 5 | T5: 6 | U5: 6 | V5: 7 | W5: 7 | X5: 9 | Y5: 9 | Z5: 10 | AA5: 10 | AB5: 11 | AC5: 11 | AD5: 12 | AE5: 12 | AF5: 14 | AG5: 14 | AH5: 15 | AI5: 15 | AJ5: =职业!$AZ$8 -> 0 | CI5: 900 | CJ5: 3 | CK5: 3环 | CL5: 3 | CM5: 4 | CN5: 2 | CO5: 1/2 | CP5: 2
A6: 5 | B6: =IF(法术书!X7="","",法术书!X7) | C6: =IFERROR(VLOOKUP(B6,法术大全!$A:$W,5,FALSE),"") | D6: =IFERROR(VLOOKUP(B6,法术大全!$A:$W,4,FALSE),"") | E6: 5 | F6: {=IFERROR(INDEX($B$1:$B$301,SMALL(IF($B$1:$B$301<>"",ROW($B$1:$B$301),4^8),ROW(6:6)))&"","")} | H6: =IF(主要!Q70<>"",主要!Q70,"") | I6: =IF(VLOOKUP(H6,法术大全!$A$3:$E$864,4,0)="√",1,0) -> 0 | J6: =IF(VLOOKUP(H6,法术大全!$A$3:$E$864,5,0)="√",1,0) -> 0 | K6: {=IFERROR(INDEX($H$1:$H$68,SMALL(IF($H$2:$H$68<>"",ROW($H$2:$H$68),4^8),ROW(6:6)))&"","")} | M6: 矮人语 | O6: 游侠 | P6: 2 | Q6: 3 | R6: 4 | S6: 5 | T6: 6 | U6: 6 | V6: 7 | W6: 7 | X6: 9 | Y6: 9 | Z6: 10 | AA6: 10 | AB6: 11 | AC6: 11 | AD6: 12 | AE6: 12 | AF6: 14 | AG6: 14 | AH6: 15 | AI6: 15 | AJ6: =职业!$AZ$9 -> 0 | CI6: =CI5*CJ5 -> 2700 | CJ6: 4 | CK6: 4环 | CL6: 4 | CM6: 5 | CN6: 3 | CO6: 1 | CP6: 2
A7: 6 | B7: =IF(法术书!X8="","",法术书!X8) | C7: =IFERROR(VLOOKUP(B7,法术大全!$A:$W,5,FALSE),"") | D7: =IFERROR(VLOOKUP(B7,法术大全!$A:$W,4,FALSE),"") | E7: 6 | F7: {=IFERROR(INDEX($B$1:$B$301,SMALL(IF($B$1:$B$301<>"",ROW($B$1:$B$301),4^8),ROW(7:7)))&"","")} | H7: =IF(主要!Q71<>"",主要!Q71,"") | I7: =IF(VLOOKUP(H7,法术大全!$A$3:$E$864,4,0)="√",1,0) -> 0 | J7: =IF(VLOOKUP(H7,法术大全!$A$3:$E$864,5,0)="√",1,0) -> 0 | K7: {=IFERROR(INDEX($H$1:$H$68,SMALL(IF($H$2:$H$68<>"",ROW($H$2:$H$68),4^8),ROW(7:7)))&"","")} | M7: 精灵语 | O7: 术士 | P7: 2 | Q7: 4 | R7: 6 | S7: 7 | T7: 9 | U7: 10 | V7: 11 | W7: 12 | X7: 14 | Y7: 15 | Z7: 16 | AA7: 16 | AB7: 17 | AC7: 17 | AD7: 18 | AE7: 18 | AF7: 19 | AG7: 20 | AH7: 21 | AI7: 22 | AJ7: =职业!$AZ$11 -> 0 | CI7: 6500 | CJ7: 5 | CK7: 5环 | CL7: 5 | CM7: 6 | CN7: 3 | CO7: 2 | CP7: 2
A8: 7 | B8: =IF(法术书!X9="","",法术书!X9) | C8: =IFERROR(VLOOKUP(B8,法术大全!$A:$W,5,FALSE),"") | D8: =IFERROR(VLOOKUP(B8,法术大全!$A:$W,4,FALSE),"") | E8: 7 | F8: {=IFERROR(INDEX($B$1:$B$301,SMALL(IF($B$1:$B$301<>"",ROW($B$1:$B$301),4^8),ROW(8:8)))&"","")} | H8: =IF(主要!Q72<>"",主要!Q72,"") | I8: =IF(VLOOKUP(H8,法术大全!$A$3:$E$864,4,0)="√",1,0) -> 0 | J8: =IF(VLOOKUP(H8,法术大全!$A$3:$E$864,5,0)="√",1,0) -> 0 | K8: {=IFERROR(INDEX($H$1:$H$68,SMALL(IF($H$2:$H$68<>"",ROW($H$2:$H$68),4^8),ROW(8:8)))&"","")} | M8: 巨人语 | O8: 魔契师 | P8: 2 | Q8: 3 | R8: 4 | S8: 5 | T8: 6 | U8: 7 | V8: 8 | W8: 9 | X8: 10 | Y8: 10 | Z8: 11 | AA8: 11 | AB8: 12 | AC8: 12 | AD8: 13 | AE8: 13 | AF8: 14 | AG8: 14 | AH8: 15 | AI8: 15 | AJ8: =职业!$AZ$12 -> 0 | CI8: 14000 | CJ8: 6 | CK8: 6环 | CL8: 6 | CM8: 7 | CN8: 3 | CO8: 3 | CP8: 2
A9: 8 | B9: =IF(法术书!X10="","",法术书!X10) | C9: =IFERROR(VLOOKUP(B9,法术大全!$A:$W,5,FALSE),"") | D9: =IFERROR(VLOOKUP(B9,法术大全!$A:$W,4,FALSE),"") | E9: 8 | F9: {=IFERROR(INDEX($B$1:$B$301,SMALL(IF($B$1:$B$301<>"",ROW($B$1:$B$301),4^8),ROW(9:9)))&"","")} | H9: =IF(主要!Q73<>"",主要!Q73,"") | I9: =IF(VLOOKUP(H9,法术大全!$A$3:$E$864,4,0)="√",1,0) -> 0 | J9: =IF(VLOOKUP(H9,法术大全!$A$3:$E$864,5,0)="√",1,0) -> 0 | K9: {=IFERROR(INDEX($H$1:$H$68,SMALL(IF($H$2:$H$68<>"",ROW($H$2:$H$68),4^8),ROW(9:9)))&"","")} | M9: 侏儒语 | O9: 法师 | P9: 4 | Q9: 5 | R9: 6 | S9: 7 | T9: 9 | U9: 10 | V9: 11 | W9: 12 | X9: 14 | Y9: 15 | Z9: 16 | AA9: 16 | AB9: 17 | AC9: 18 | AD9: 19 | AE9: 21 | AF9: 22 | AG9: 23 | AH9: 24 | AI9: 25 | AJ9: =职业!$AZ$13 -> 0 | CI9: 23000 | CJ9: 7 | CK9: 7环 | CL9: 7 | CM9: 8 | CN9: 3 | CO9: 4 | CP9: 2
A10: 9 | B10: =IF(法术书!X11="","",法术书!X11) | C10: =IFERROR(VLOOKUP(B10,法术大全!$A:$W,5,FALSE),"") | D10: =IFERROR(VLOOKUP(B10,法术大全!$A:$W,4,FALSE),"") | E10: 9 | F10: {=IFERROR(INDEX($B$1:$B$301,SMALL(IF($B$1:$B$301<>"",ROW($B$1:$B$301),4^8),ROW(10:10)))&"","")} | G10: 戏法1 | H10: =IF(主要!Q77<>"",主要!Q77,"") | I10: =IF(VLOOKUP(H10,法术大全!$A$3:$E$864,4,0)="√",1,0) -> 0 | J10: =IF(VLOOKUP(H10,法术大全!$A$3:$E$864,5,0)="√",1,0) -> 0 | K10: {=IFERROR(INDEX($H$1:$H$68,SMALL(IF($H$2:$H$68<>"",ROW($H$2:$H$68),4^8),ROW(10:10)))&"","")} | M10: 地精语 | O10: 奇械师 | P10: 2 | Q10: 3 | R10: 4 | S10: 5 | T10: 6 | U10: 6 | V10: 7 | W10: 7 | X10: 9 | Y10: 9 | Z10: 10 | AA10: 10 | AB10: 11 | AC10: 11 | AD10: 12 | AE10: 12 | AF10: 14 | AG10: 14 | AH10: 15 | AI10: 15 | AJ10: =职业!$AZ$14 -> 0 | CI10: 34000 | CJ10: 8 | CK10: 8环 | CL10: 8 | CM10: 9 | CN10: 4 | CO10: 5 | CP10: 3
A11: 10 | B11: =IF(法术书!X12="","",法术书!X12) | C11: =IFERROR(VLOOKUP(B11,法术大全!$A:$W,5,FALSE),"") | D11: =IFERROR(VLOOKUP(B11,法术大全!$A:$W,4,FALSE),"") | E11: 10 | F11: {=IFERROR(INDEX($B$1:$B$301,SMALL(IF($B$1:$B$301<>"",ROW($B$1:$B$301),4^8),ROW(11:11)))&"","")} | H11: =IF(主要!Q78<>"",主要!Q78,"") | I11: =IF(VLOOKUP(H11,法术大全!$A$3:$E$864,4,0)="√",1,0) -> 0 | J11: =IF(VLOOKUP(H11,法术大全!$A$3:$E$864,5,0)="√",1,0) -> 0 | K11: {=IFERROR(INDEX($H$1:$H$68,SMALL(IF($H$2:$H$68<>"",ROW($H$2:$H$68),4^8),ROW(11:11)))&"","")} | M11: 半身人语 | O11: 药剂师 | P11: =职业!$AZ$17+主要!$R$16 -> 0 | Q11: =职业!$AZ$17+主要!$R$16 -> 0 | R11: =职业!$AZ$17+主要!$R$16 -> 0 | S11: =职业!$AZ$17+主要!$R$16 -> 0 | T11: =职业!$AZ$17+主要!$R$16 -> 0 | U11: =职业!$AZ$17+主要!$R$16 -> 0 | V11: =职业!$AZ$17+主要!$R$16 -> 0 | W11: =职业!$AZ$17+主要!$R$16 -> 0 | ... AI11: =职业!$AZ$17+主要!$R$16 -> 0 | AJ11: =职业!$AZ$17 -> 0 | CI11: 48000 | CJ11: 9 | CK11: 9环 | CL11: 9 | CM11: 10 | CN11: 4 | CO11: 6 | CP11: 3
A12: 11 | B12: =IF(法术书!X13="","",法术书!X13) | C12: =IFERROR(VLOOKUP(B12,法术大全!$A:$W,5,FALSE),"") | D12: =IFERROR(VLOOKUP(B12,法术大全!$A:$W,4,FALSE),"") | E12: 11 | F12: {=IFERROR(INDEX($B$1:$B$301,SMALL(IF($B$1:$B$301<>"",ROW($B$1:$B$301),4^8),ROW(12:12)))&"","")} | H12: =IF(主要!Q79<>"",主要!Q79,"") | I12: =IF(VLOOKUP(H12,法术大全!$A$3:$E$864,4,0)="√",1,0) -> 0 | J12: =IF(VLOOKUP(H12,法术大全!$A$3:$E$864,5,0)="√",1,0) -> 0 | K12: {=IFERROR(INDEX($H$1:$H$68,SMALL(IF($H$2:$H$68<>"",ROW($H$2:$H$68),4^8),ROW(12:12)))&"","")} | M12: 兽人语 | O12: 灵能使 | P12: 4 | Q12: 5 | R12: 6 | S12: 7 | T12: 9 | U12: 10 | V12: 11 | W12: 12 | X12: 14 | Y12: 15 | Z12: 16 | AA12: 16 | AB12: 17 | AC12: 17 | AD12: 18 | AE12: 18 | AF12: 19 | AG12: 20 | AH12: 21 | AI12: 22 | AJ12: =职业!$AZ$15 -> 0 | CI12: 64000 | CJ12: 10 | CM12: 11 | CN12: 4 | CO12: 7 | CP12: 3
A13: 12 | B13: =IF(法术书!X14="","",法术书!X14) | C13: =IFERROR(VLOOKUP(B13,法术大全!$A:$W,5,FALSE),"") | D13: =IFERROR(VLOOKUP(B13,法术大全!$A:$W,4,FALSE),"") | E13: 12 | F13: {=IFERROR(INDEX($B$1:$B$301,SMALL(IF($B$1:$B$301<>"",ROW($B$1:$B$301),4^8),ROW(13:13)))&"","")} | H13: =IF(主要!Q80<>"",主要!Q80,"") | I13: =IF(VLOOKUP(H13,法术大全!$A$3:$E$864,4,0)="√",1,0) -> 0 | J13: =IF(VLOOKUP(H13,法术大全!$A$3:$E$864,5,0)="√",1,0) -> 0 | K13: {=IFERROR(INDEX($H$1:$H$68,SMALL(IF($H$2:$H$68<>"",ROW($H$2:$H$68),4^8),ROW(13:13)))&"","")} | M13: —稀有语言— | O13: 奥法骑士 | P13: 0 | Q13: 0 | R13: 3 | S13: 4 | T13: 4 | U13: 4 | V13: 5 | W13: 6 | X13: 6 | Y13: 7 | Z13: 8 | AA13: 8 | AB13: 9 | AC13: 10 | AD13: 10 | AE13: 11 | AF13: 11 | AG13: 11 | AH13: 12 | AI13: 13 | AJ13: =职业!$BB$6 -> 0 | CI13: 85000 | CJ13: 11 | CM13: 12 | CN13: 4 | CO13: 8 | CP13: 3
A14: 13 | B14: =IF(法术书!X15="","",法术书!X15) | C14: =IFERROR(VLOOKUP(B14,法术大全!$A:$W,5,FALSE),"") | D14: =IFERROR(VLOOKUP(B14,法术大全!$A:$W,4,FALSE),"") | E14: 13 | F14: {=IFERROR(INDEX($B$1:$B$301,SMALL(IF($B$1:$B$301<>"",ROW($B$1:$B$301),4^8),ROW(14:14)))&"","")} | H14: =IF(主要!Q81<>"",主要!Q81,"") | I14: =IF(VLOOKUP(H14,法术大全!$A$3:$E$864,4,0)="√",1,0) -> 0 | J14: =IF(VLOOKUP(H14,法术大全!$A$3:$E$864,5,0)="√",1,0) -> 0 | K14: {=IFERROR(INDEX($H$1:$H$68,SMALL(IF($H$2:$H$68<>"",ROW($H$2:$H$68),4^8),ROW(14:14)))&"","")} | M14: 深渊语 | O14: 诡术师 | P14: 0 | Q14: 0 | R14: 3 | S14: 4 | T14: 4 | U14: 4 | V14: 5 | W14: 6 | X14: 6 | Y14: 7 | Z14: 8 | AA14: 8 | AB14: 9 | AC14: 10 | AD14: 10 | AE14: 11 | AF14: 11 | AG14: 11 | AH14: 12 | AI14: 13 | AJ14: =职业!$BB$7 -> 0 | CI14: 100000 | CJ14: 12 | CM14: 13 | CN14: 5 | CO14: 9 | CP14: 4
A15: 14 | B15: =IF(法术书!X16="","",法术书!X16) | C15: =IFERROR(VLOOKUP(B15,法术大全!$A:$W,5,FALSE),"") | D15: =IFERROR(VLOOKUP(B15,法术大全!$A:$W,4,FALSE),"") | E15: 14 | F15: {=IFERROR(INDEX($B$1:$B$301,SMALL(IF($B$1:$B$301<>"",ROW($B$1:$B$301),4^8),ROW(15:15)))&"","")} | G15: 戏法2 | H15: =IF(主要!Y77<>"",主要!Y77,"") | I15: =IF(VLOOKUP(H15,法术大全!$A$3:$E$864,4,0)="√",1,0) -> 0 | J15: =IF(VLOOKUP(H15,法术大全!$A$3:$E$864,5,0)="√",1,0) -> 0 | K15: {=IFERROR(INDEX($H$1:$H$68,SMALL(IF($H$2:$H$68<>"",ROW($H$2:$H$68),4^8),ROW(15:15)))&"","")} | M15: 天界语 | O15: 渎魂圣约 | P15: 0 | Q15: 0 | R15: 2 | S15: 2 | T15: 3 | U15: 3 | V15: 4 | W15: 4 | X15: 5 | Y15: 5 | Z15: 6 | AA15: 6 | AB15: 7 | AC15: 7 | AD15: 8 | AE15: 8 | AF15: 9 | AG15: 9 | AH15: 10 | AI15: 11 | AJ15: =职业!$AX$17 -> 0 | AO15: 特性 | AX15: HD | AZ15: 数量 | CI15: 120000 | CJ15: 13 | CL15: 体型 | CM15: 14 | CN15: 5 | CO15: 10 | CP15: 4
A16: 15 | B16: =IF(法术书!X17="","",法术书!X17) | C16: =IFERROR(VLOOKUP(B16,法术大全!$A:$W,5,FALSE),"") | D16: =IFERROR(VLOOKUP(B16,法术大全!$A:$W,4,FALSE),"") | E16: 15 | F16: {=IFERROR(INDEX($B$1:$B$301,SMALL(IF($B$1:$B$301<>"",ROW($B$1:$B$301),4^8),ROW(16:16)))&"","")} | H16: =IF(主要!Y78<>"",主要!Y78,"") | I16: =IF(VLOOKUP(H16,法术大全!$A$3:$E$864,4,0)="√",1,0) -> 0 | J16: =IF(VLOOKUP(H16,法术大全!$A$3:$E$864,5,0)="√",1,0) -> 0 | K16: {=IFERROR(INDEX($H$1:$H$68,SMALL(IF($H$2:$H$68<>"",ROW($H$2:$H$68),4^8),ROW(16:16)))&"","")} | M16: 深潜语 | O16: 筑灭师 | P16: 0 | Q16: 0 | R16: 3 | S16: 4 | T16: 4 | U16: 4 | V16: 5 | W16: 6 | X16: 6 | Y16: 7 | Z16: 8 | AA16: 8 | AB16: 9 | AC16: 10 | AD16: 10 | AE16: 11 | AF16: 11 | AG16: 11 | AH16: 12 | AI16: 13 | AJ16: =职业!$BB$8 -> 0 | AX16: D6 | CI16: 140000 | CJ16: 14 | CL16: 微型 | CM16: 15 | CN16: 5 | CO16: 11 | CP16: 4
A17: 16 | B17: =IF(法术书!X18="","",法术书!X18) | C17: =IFERROR(VLOOKUP(B17,法术大全!$A:$W,5,FALSE),"") | D17: =IFERROR(VLOOKUP(B17,法术大全!$A:$W,4,FALSE),"") | E17: 16 | F17: {=IFERROR(INDEX($B$1:$B$301,SMALL(IF($B$1:$B$301<>"",ROW($B$1:$B$301),4^8),ROW(17:17)))&"","")} | H17: =IF(主要!Y79<>"",主要!Y79,"") | I17: =IF(VLOOKUP(H17,法术大全!$A$3:$E$864,4,0)="√",1,0) -> 0 | J17: =IF(VLOOKUP(H17,法术大全!$A$3:$E$864,5,0)="√",1,0) -> 0 | K17: {=IFERROR(INDEX($H$1:$H$68,SMALL(IF($H$2:$H$68<>"",ROW($H$2:$H$68),4^8),ROW(17:17)))&"","")} | M17: 德鲁伊语 | O17: 魔弹客 | P17: 0 | Q17: 0 | R17: 3 | S17: 4 | T17: 4 | U17: 4 | V17: 5 | W17: 6 | X17: 6 | Y17: 7 | Z17: 8 | AA17: 8 | AB17: 9 | AC17: 10 | AD17: 10 | AE17: 11 | AF17: 11 | AG17: 11 | AH17: 12 | AI17: 13 | AJ17: =职业!$BB$9 -> 0 | AX17: D8 | CI17: 165000 | CJ17: 15 | CL17: 小型 | CM17: 16 | CN17: 5 | CO17: 12 | CP17: 4
A18: 17 | B18: =IF(法术书!X19="","",法术书!X19) | C18: =IFERROR(VLOOKUP(B18,法术大全!$A:$W,5,FALSE),"") | D18: =IFERROR(VLOOKUP(B18,法术大全!$A:$W,4,FALSE),"") | E18: 17 | F18: {=IFERROR(INDEX($B$1:$B$301,SMALL(IF($B$1:$B$301<>"",ROW($B$1:$B$301),4^8),ROW(18:18)))&"","")} | H18: =IF(主要!Y80<>"",主要!Y80,"") | I18: =IF(VLOOKUP(H18,法术大全!$A$3:$E$864,4,0)="√",1,0) -> 0 | J18: =IF(VLOOKUP(H18,法术大全!$A$3:$E$864,5,0)="√",1,0) -> 0 | K18: {=IFERROR(INDEX($H$1:$H$68,SMALL(IF($H$2:$H$68<>"",ROW($H$2:$H$68),4^8),ROW(18:18)))&"","")} | M18: 炼狱语 | O18: 织法宗 | P18: 0 | Q18: 0 | R18: 3 | S18: 4 | T18: 4 | U18: 4 | V18: 5 | W18: 6 | X18: 6 | Y18: 7 | Z18: 8 | AA18: 8 | AB18: 9 | AC18: 10 | AD18: 10 | AE18: 11 | AF18: 11 | AG18: 11 | AH18: 12 | AI18: 13 | AJ18: =职业!$BB$10 -> 0 | AX18: D10 | CI18: 195000 | CJ18: 16 | CL18: 中型 | CM18: 17 | CN18: 6 | CO18: 13 | CP18: 5
A19: 18 | B19: =IF(法术书!X20="","",法术书!X20) | C19: =IFERROR(VLOOKUP(B19,法术大全!$A:$W,5,FALSE),"") | D19: =IFERROR(VLOOKUP(B19,法术大全!$A:$W,4,FALSE),"") | E19: 18 | F19: {=IFERROR(INDEX($B$1:$B$301,SMALL(IF($B$1:$B$301<>"",ROW($B$1:$B$301),4^8),ROW(19:19)))&"","")} | H19: =IF(主要!Y81<>"",主要!Y81,"") | I19: =IF(VLOOKUP(H19,法术大全!$A$3:$E$864,4,0)="√",1,0) -> 0 | J19: =IF(VLOOKUP(H19,法术大全!$A$3:$E$864,5,0)="√",1,0) -> 0 | K19: {=IFERROR(INDEX($H$1:$H$68,SMALL(IF($H$2:$H$68<>"",ROW($H$2:$H$68),4^8),ROW(19:19)))&"","")} | M19: 原初语 | O19: 秘术武者 | P19: 0 | Q19: 0 | R19: 3 | S19: 4 | T19: 4 | U19: 4 | V19: 5 | W19: 6 | X19: 6 | Y19: 7 | Z19: 8 | AA19: 8 | AB19: 9 | AC19: 10 | AD19: 10 | AE19: 11 | AF19: 11 | AG19: 11 | AH19: 12 | AI19: 13 | AJ19: =职业!$BB$11 -> 0 | CI19: 225000 | CJ19: 17 | CL19: 大型 | CM19: 18 | CN19: 6 | CO19: 14 | CP19: 5
A20: 19 | B20: =IF(法术书!X21="","",法术书!X21) | C20: =IFERROR(VLOOKUP(B20,法术大全!$A:$W,5,FALSE),"") | D20: =IFERROR(VLOOKUP(B20,法术大全!$A:$W,4,FALSE),"") | E20: 19 | F20: {=IFERROR(INDEX($B$1:$B$301,SMALL(IF($B$1:$B$301<>"",ROW($B$1:$B$301),4^8),ROW(20:20)))&"","")} | G20: 列1 | H20: =IF(主要!Y66<>"",主要!Y66,"") | I20: =IF(VLOOKUP(H20,法术大全!$A$3:$E$864,4,0)="√",1,0) -> 0 | J20: =IF(VLOOKUP(H20,法术大全!$A$3:$E$864,5,0)="√",1,0) -> 0 | K20: {=IFERROR(INDEX($H$1:$H$68,SMALL(IF($H$2:$H$68<>"",ROW($H$2:$H$68),4^8),ROW(20:20)))&"","")} | M20: 木族语 | CI20: 265000 | CJ20: 18 | CL20: 巨型 | CM20: 19 | CN20: 6 | CO20: 15 | CP20: 5
A21: 20 | B21: =IF(法术书!X22="","",法术书!X22) | C21: =IFERROR(VLOOKUP(B21,法术大全!$A:$W,5,FALSE),"") | D21: =IFERROR(VLOOKUP(B21,法术大全!$A:$W,4,FALSE),"") | E21: 20 | F21: {=IFERROR(INDEX($B$1:$B$301,SMALL(IF($B$1:$B$301<>"",ROW($B$1:$B$301),4^8),ROW(21:21)))&"","")} | H21: =IF(主要!Y67<>"",主要!Y67,"") | I21: =IF(VLOOKUP(H21,法术大全!$A$3:$E$864,4,0)="√",1,0) -> 0 | J21: =IF(VLOOKUP(H21,法术大全!$A$3:$E$864,5,0)="√",1,0) -> 0 | K21: {=IFERROR(INDEX($H$1:$H$68,SMALL(IF($H$2:$H$68<>"",ROW($H$2:$H$68),4^8),ROW(21:21)))&"","")} | M21: 盗贼黑话 | AL21: ———随身钱币——— | CI21: 305000 | CJ21: 19 | CL21: 超巨型 | CM21: 20 | CN21: 6 | CO21: 16 | CP21: 5
A22: 21 | B22: =IF(法术书!X23="","",法术书!X23) | C22: =IFERROR(VLOOKUP(B22,法术大全!$A:$W,5,FALSE),"") | D22: =IFERROR(VLOOKUP(B22,法术大全!$A:$W,4,FALSE),"") | E22: 21 | F22: {=IFERROR(INDEX($B$1:$B$301,SMALL(IF($B$1:$B$301<>"",ROW($B$1:$B$301),4^8),ROW(22:22)))&"","")} | H22: =IF(主要!Y68<>"",主要!Y68,"") | I22: =IF(VLOOKUP(H22,法术大全!$A$3:$E$864,4,0)="√",1,0) -> 0 | J22: =IF(VLOOKUP(H22,法术大全!$A$3:$E$864,5,0)="√",1,0) -> 0 | K22: {=IFERROR(INDEX($H$1:$H$68,SMALL(IF($H$2:$H$68<>"",ROW($H$2:$H$68),4^8),ROW(22:22)))&"","")} | M22: 地底通用语 | O22: 主职业 | P22: =主要!E6 -> 0 | Q22: =IFERROR(VLOOKUP(P22,$O$2:$AI$11,主要!O6+1,0),"") | AL22: CP | AS22: SP | AZ22: EP | BG22: GP | BN22: PP | BU22: 总计 | BX22: =CONCATENATE(SUM(BP22*10+BB22/2+BI22+AU22/10+AN22/100),"GP") -> 0GP | CI22: 355000 | CJ22: 20 | CO22: 17 | CP22: 6
A23: 22 | B23: =IF(法术书!X24="","",法术书!X24) | C23: =IFERROR(VLOOKUP(B23,法术大全!$A:$W,5,FALSE),"") | D23: =IFERROR(VLOOKUP(B23,法术大全!$A:$W,4,FALSE),"") | E23: 22 | F23: {=IFERROR(INDEX($B$1:$B$301,SMALL(IF($B$1:$B$301<>"",ROW($B$1:$B$301),4^8),ROW(23:23)))&"","")} | H23: =IF(主要!Y69<>"",主要!Y69,"") | I23: =IF(VLOOKUP(H23,法术大全!$A$3:$E$864,4,0)="√",1,0) -> 0 | J23: =IF(VLOOKUP(H23,法术大全!$A$3:$E$864,5,0)="√",1,0) -> 0 | K23: {=IFERROR(INDEX($H$1:$H$68,SMALL(IF($H$2:$H$68<>"",ROW($H$2:$H$68),4^8),ROW(23:23)))&"","")} | O23: 兼职1 | P23: =主要!E7 -> 0 | Q23: =IFERROR(VLOOKUP(P23,$O$2:$AI$11,主要!O7+1,0),"") | CI23: =_xlfn.XLOOKUP(VLOOKUP(主要!E9,CI3:CJ22,2,TRUE), CJ3:CJ22, CI3:CI22, 0) -> 0 | CJ23: =_xlfn.XLOOKUP(VLOOKUP(主要!E9,CI3:CJ22,2,TRUE)+1, CJ3:CJ22, CI3:CI22, 355000) -> 300 | CO23: 18 | CP23: 6
A24: 23 | B24: =IF(法术书!X25="","",法术书!X25) | C24: =IFERROR(VLOOKUP(B24,法术大全!$A:$W,5,FALSE),"") | D24: =IFERROR(VLOOKUP(B24,法术大全!$A:$W,4,FALSE),"") | E24: 23 | F24: {=IFERROR(INDEX($B$1:$B$301,SMALL(IF($B$1:$B$301<>"",ROW($B$1:$B$301),4^8),ROW(24:24)))&"","")} | H24: =IF(主要!Y70<>"",主要!Y70,"") | I24: =IF(VLOOKUP(H24,法术大全!$A$3:$E$864,4,0)="√",1,0) -> 0 | J24: =IF(VLOOKUP(H24,法术大全!$A$3:$E$864,5,0)="√",1,0) -> 0 | K24: {=IFERROR(INDEX($H$1:$H$68,SMALL(IF($H$2:$H$68<>"",ROW($H$2:$H$68),4^8),ROW(24:24)))&"","")} | O24: 兼职2 | P24: =主要!E8 -> 0 | Q24: =IFERROR(VLOOKUP(P24,$O$2:$AI$11,主要!O8+1,0),"") | CO24: 19 | CP24: 6
A25: 24 | B25: =IF(法术书!X26="","",法术书!X26) | C25: =IFERROR(VLOOKUP(B25,法术大全!$A:$W,5,FALSE),"") | D25: =IFERROR(VLOOKUP(B25,法术大全!$A:$W,4,FALSE),"") | E25: 24 | F25: {=IFERROR(INDEX($B$1:$B$301,SMALL(IF($B$1:$B$301<>"",ROW($B$1:$B$301),4^8),ROW(25:25)))&"","")} | H25: =IF(主要!Y71<>"",主要!Y71,"") | I25: =IF(VLOOKUP(H25,法术大全!$A$3:$E$864,4,0)="√",1,0) -> 0 | J25: =IF(VLOOKUP(H25,法术大全!$A$3:$E$864,5,0)="√",1,0) -> 0 | K25: {=IFERROR(INDEX($H$1:$H$68,SMALL(IF($H$2:$H$68<>"",ROW($H$2:$H$68),4^8),ROW(25:25)))&"","")} | CO25: 20 | CP25: 6
A26: 25 | B26: =IF(法术书!X27="","",法术书!X27) | C26: =IFERROR(VLOOKUP(B26,法术大全!$A:$W,5,FALSE),"") | D26: =IFERROR(VLOOKUP(B26,法术大全!$A:$W,4,FALSE),"") | E26: 25 | F26: {=IFERROR(INDEX($B$1:$B$301,SMALL(IF($B$1:$B$301<>"",ROW($B$1:$B$301),4^8),ROW(26:26)))&"","")} | H26: =IF(主要!Y72<>"",主要!Y72,"") | I26: =IF(VLOOKUP(H26,法术大全!$A$3:$E$864,4,0)="√",1,0) -> 0 | J26: =IF(VLOOKUP(H26,法术大全!$A$3:$E$864,5,0)="√",1,0) -> 0 | K26: {=IFERROR(INDEX($H$1:$H$68,SMALL(IF($H$2:$H$68<>"",ROW($H$2:$H$68),4^8),ROW(26:26)))&"","")} | O26: 准备法术 | P26: =IFERROR(VLOOKUP(主要!$B$70,$O$2:$AI$19, IF(VLOOKUP(主要!$B$70,$O$2:$AJ$19,22,FALSE)=0,"",VLOOKUP(主要!$B$70,$O$2:$AJ$19,22,FALSE)+1), FALSE),"") | AL26: 背包 | BP26: 重量 | BS26: 重量 | BV26: 重量 | BY26: 重量 | CB26: 重量 | CO26: 21 | CP26: 7
A27: 26 | B27: =IF(法术书!X28="","",法术书!X28) | C27: =IFERROR(VLOOKUP(B27,法术大全!$A:$W,5,FALSE),"") | D27: =IFERROR(VLOOKUP(B27,法术大全!$A:$W,4,FALSE),"") | E27: 26 | F27: {=IFERROR(INDEX($B$1:$B$301,SMALL(IF($B$1:$B$301<>"",ROW($B$1:$B$301),4^8),ROW(27:27)))&"","")} | H27: =IF(主要!Y73<>"",主要!Y73,"") | I27: =IF(VLOOKUP(H27,法术大全!$A$3:$E$864,4,0)="√",1,0) -> 0 | J27: =IF(VLOOKUP(H27,法术大全!$A$3:$E$864,5,0)="√",1,0) -> 0 | K27: {=IFERROR(INDEX($H$1:$H$68,SMALL(IF($H$2:$H$68<>"",ROW($H$2:$H$68),4^8),ROW(27:27)))&"","")} | R27: =IFERROR(VLOOKUP(主要!$B$70,$O$2:$AI$19, IF(VLOOKUP(主要!$B$70,职业!$AY$2:$AZ$20,2,FALSE)=0,"",VLOOKUP(主要!$B$70,职业!$AY$2:$AZ$20,2,FALSE)+1), FALSE),"") | AL27: 装备 | AR27: 稀有度 | AU27: 部位 | AW27: 描述 | BP27: =装备!AX12 | BS27: =IF(主要!AS40="否","",6) | BV27: =装备!AY2 | CO27: 22 | CP27: 7
A28: 27 | B28: =IF(法术书!X29="","",法术书!X29) | C28: =IFERROR(VLOOKUP(B28,法术大全!$A:$W,5,FALSE),"") | D28: =IFERROR(VLOOKUP(B28,法术大全!$A:$W,4,FALSE),"") | E28: 27 | F28: {=IFERROR(INDEX($B$1:$B$301,SMALL(IF($B$1:$B$301<>"",ROW($B$1:$B$301),4^8),ROW(28:28)))&"","")} | G28: 列2 | H28: =IF(主要!AG66<>"",主要!AG66,"") | I28: =IF(VLOOKUP(H28,法术大全!$A$3:$E$864,4,0)="√",1,0) -> 0 | J28: =IF(VLOOKUP(H28,法术大全!$A$3:$E$864,5,0)="√",1,0) -> 0 | K28: {=IFERROR(INDEX($H$1:$H$68,SMALL(IF($H$2:$H$68<>"",ROW($H$2:$H$68),4^8),ROW(28:28)))&"","")} | AQ28: > | BV28: =装备!AY3 | CO28: 23 | CP28: 7
A29: 28 | B29: =IF(法术书!X30="","",法术书!X30) | C29: =IFERROR(VLOOKUP(B29,法术大全!$A:$W,5,FALSE),"") | D29: =IFERROR(VLOOKUP(B29,法术大全!$A:$W,4,FALSE),"") | E29: 28 | F29: {=IFERROR(INDEX($B$1:$B$301,SMALL(IF($B$1:$B$301<>"",ROW($B$1:$B$301),4^8),ROW(29:29)))&"","")} | H29: =IF(主要!AG67<>"",主要!AG67,"") | I29: =IF(VLOOKUP(H29,法术大全!$A$3:$E$864,4,0)="√",1,0) -> 0 | J29: =IF(VLOOKUP(H29,法术大全!$A$3:$E$864,5,0)="√",1,0) -> 0 | K29: {=IFERROR(INDEX($H$1:$H$68,SMALL(IF($H$2:$H$68<>"",ROW($H$2:$H$68),4^8),ROW(29:29)))&"","")} | AQ29: > | BV29: =装备!AY4 | CO29: 24 | CP29: 7
A30: 29 | B30: =IF(法术书!X31="","",法术书!X31) | C30: =IFERROR(VLOOKUP(B30,法术大全!$A:$W,5,FALSE),"") | D30: =IFERROR(VLOOKUP(B30,法术大全!$A:$W,4,FALSE),"") | E30: 29 | F30: {=IFERROR(INDEX($B$1:$B$301,SMALL(IF($B$1:$B$301<>"",ROW($B$1:$B$301),4^8),ROW(30:30)))&"","")} | H30: =IF(主要!AG68<>"",主要!AG68,"") | I30: =IF(VLOOKUP(H30,法术大全!$A$3:$E$864,4,0)="√",1,0) -> 0 | J30: =IF(VLOOKUP(H30,法术大全!$A$3:$E$864,5,0)="√",1,0) -> 0 | K30: {=IFERROR(INDEX($H$1:$H$68,SMALL(IF($H$2:$H$68<>"",ROW($H$2:$H$68),4^8),ROW(30:30)))&"","")} | AQ30: > | BV30: =装备!AY5 | CO30: 25 | CP30: 8
A31: 30 | B31: =IF(法术书!X32="","",法术书!X32) | C31: =IFERROR(VLOOKUP(B31,法术大全!$A:$W,5,FALSE),"") | D31: =IFERROR(VLOOKUP(B31,法术大全!$A:$W,4,FALSE),"") | E31: 30 | F31: {=IFERROR(INDEX($B$1:$B$301,SMALL(IF($B$1:$B$301<>"",ROW($B$1:$B$301),4^8),ROW(31:31)))&"","")} | H31: =IF(主要!AG69<>"",主要!AG69,"") | I31: =IF(VLOOKUP(H31,法术大全!$A$3:$E$864,4,0)="√",1,0) -> 0 | J31: =IF(VLOOKUP(H31,法术大全!$A$3:$E$864,5,0)="√",1,0) -> 0 | K31: {=IFERROR(INDEX($H$1:$H$68,SMALL(IF($H$2:$H$68<>"",ROW($H$2:$H$68),4^8),ROW(31:31)))&"","")} | AQ31: > | BV31: =装备!AY6 | CO31: 26 | CP31: 8
A32: 31 | B32: =IF(法术书!X33="","",法术书!X33) | C32: =IFERROR(VLOOKUP(B32,法术大全!$A:$W,5,FALSE),"") | D32: =IFERROR(VLOOKUP(B32,法术大全!$A:$W,4,FALSE),"") | E32: 31 | F32: {=IFERROR(INDEX($B$1:$B$301,SMALL(IF($B$1:$B$301<>"",ROW($B$1:$B$301),4^8),ROW(32:32)))&"","")} | H32: =IF(主要!AG70<>"",主要!AG70,"") | I32: =IF(VLOOKUP(H32,法术大全!$A$3:$E$864,4,0)="√",1,0) -> 0 | J32: =IF(VLOOKUP(H32,法术大全!$A$3:$E$864,5,0)="√",1,0) -> 0 | K32: {=IFERROR(INDEX($H$1:$H$68,SMALL(IF($H$2:$H$68<>"",ROW($H$2:$H$68),4^8),ROW(32:32)))&"","")} | V32: 计算 | AQ32: > | CO32: 27 | CP32: 8
A33: 32 | B33: =IF(法术书!X34="","",法术书!X34) | C33: =IFERROR(VLOOKUP(B33,法术大全!$A:$W,5,FALSE),"") | D33: =IFERROR(VLOOKUP(B33,法术大全!$A:$W,4,FALSE),"") | E33: 32 | F33: {=IFERROR(INDEX($B$1:$B$301,SMALL(IF($B$1:$B$301<>"",ROW($B$1:$B$301),4^8),ROW(33:33)))&"","")} | H33: =IF(主要!AG71<>"",主要!AG71,"") | I33: =IF(VLOOKUP(H33,法术大全!$A$3:$E$864,4,0)="√",1,0) -> 0 | J33: =IF(VLOOKUP(H33,法术大全!$A$3:$E$864,5,0)="√",1,0) -> 0 | K33: {=IFERROR(INDEX($H$1:$H$68,SMALL(IF($H$2:$H$68<>"",ROW($H$2:$H$68),4^8),ROW(33:33)))&"","")} | W33: D6 | X33: D8 | Y33: D10 | Z33: D12 | AL33: 消耗品 | AR33: 描述 | BC33: 数量 | BP33: 隐匿劣势 | BT33: 无 | CO33: 28 | CP33: 8
A34: 33 | B34: =IF(法术书!X35="","",法术书!X35) | C34: =IFERROR(VLOOKUP(B34,法术大全!$A:$W,5,FALSE),"") | D34: =IFERROR(VLOOKUP(B34,法术大全!$A:$W,4,FALSE),"") | E34: 33 | F34: {=IFERROR(INDEX($B$1:$B$301,SMALL(IF($B$1:$B$301<>"",ROW($B$1:$B$301),4^8),ROW(34:34)))&"","")} | H34: =IF(主要!AG72<>"",主要!AG72,"") | I34: =IF(VLOOKUP(H34,法术大全!$A$3:$E$864,4,0)="√",1,0) -> 0 | J34: =IF(VLOOKUP(H34,法术大全!$A$3:$E$864,5,0)="√",1,0) -> 0 | K34: {=IFERROR(INDEX($H$1:$H$68,SMALL(IF($H$2:$H$68<>"",ROW($H$2:$H$68),4^8),ROW(34:34)))&"","")} | P34: 戏法 | Q34: 变化 | R34: 动作 | S34: 触及 | T34: 立即 | W34: =IF(自定义调整栏!$V$23=0,0,SUM($W$35:INDEX($W$35:$W$54,自定义调整栏!$V$23,1))) -> 0 | X34: =IF(自定义调整栏!$X$23=0,0,SUM($X$35:INDEX($X$35:$X$54,自定义调整栏!$X$23,1))) -> 0 | Y34: =IF(自定义调整栏!$Z$23=0,0,SUM($Y$35:INDEX($Y$35:$Y$54,自定义调整栏!$Z$23,1))) -> 0 | Z34: =IF(自定义调整栏!$AB$23=0,0,SUM($Z$35:INDEX($Z$35:$Z$54,自定义调整栏!$AB$23,1))) -> 0 | AQ34: > | BE34: / | CO34: 29 | CP34: 9
A35: 34 | B35: =IF(法术书!X36="","",法术书!X36) | C35: =IFERROR(VLOOKUP(B35,法术大全!$A:$W,5,FALSE),"") | D35: =IFERROR(VLOOKUP(B35,法术大全!$A:$W,4,FALSE),"") | E35: 34 | F35: {=IFERROR(INDEX($B$1:$B$301,SMALL(IF($B$1:$B$301<>"",ROW($B$1:$B$301),4^8),ROW(35:35)))&"","")} | H35: =IF(主要!AG73<>"",主要!AG73,"") | I35: =IF(VLOOKUP(H35,法术大全!$A$3:$E$864,4,0)="√",1,0) -> 0 | J35: =IF(VLOOKUP(H35,法术大全!$A$3:$E$864,5,0)="√",1,0) -> 0 | K35: {=IFERROR(INDEX($H$1:$H$68,SMALL(IF($H$2:$H$68<>"",ROW($H$2:$H$68),4^8),ROW(35:35)))&"","")} | P35: 1 | Q35: 塑能 | R35: 附赠动作 | S35: 自身 | T35: 1轮 | V35: 1 | W35: =RANDBETWEEN(1,6) -> 1 | X35: =RANDBETWEEN(1,8) -> 3 | Y35: =RANDBETWEEN(1,10) -> 6 | Z35: =RANDBETWEEN(1,12) -> 2 | AQ35: > | BE35: / | CO35: 30 | CP35: 9
A36: 35 | B36: =IF(法术书!X37="","",法术书!X37) | C36: =IFERROR(VLOOKUP(B36,法术大全!$A:$W,5,FALSE),"") | D36: =IFERROR(VLOOKUP(B36,法术大全!$A:$W,4,FALSE),"") | E36: 35 | F36: {=IFERROR(INDEX($B$1:$B$301,SMALL(IF($B$1:$B$301<>"",ROW($B$1:$B$301),4^8),ROW(36:36)))&"","")} | H36: =IF(主要!AG74<>"",主要!AG74,"") | I36: =IF(VLOOKUP(H36,法术大全!$A$3:$E$864,4,0)="√",1,0) -> 0 | J36: =IF(VLOOKUP(H36,法术大全!$A$3:$E$864,5,0)="√",1,0) -> 0 | K36: {=IFERROR(INDEX($H$1:$H$68,SMALL(IF($H$2:$H$68<>"",ROW($H$2:$H$68),4^8),ROW(36:36)))&"","")} | P36: 2 | Q36: 防护 | R36: 1分钟 | S36: 15尺 | T36: 1分钟 | V36: 2 | W36: =RANDBETWEEN(1,6) -> 2 | X36: =RANDBETWEEN(1,8) -> 8 | Y36: =RANDBETWEEN(1,10) -> 8 | Z36: =RANDBETWEEN(1,12) -> 12 | AQ36: > | BE36: /
A37: 36 | B37: =IF(法术书!X38="","",法术书!X38) | C37: =IFERROR(VLOOKUP(B37,法术大全!$A:$W,5,FALSE),"") | D37: =IFERROR(VLOOKUP(B37,法术大全!$A:$W,4,FALSE),"") | E37: 36 | F37: {=IFERROR(INDEX($B$1:$B$301,SMALL(IF($B$1:$B$301<>"",ROW($B$1:$B$301),4^8),ROW(37:37)))&"","")} | H37: =IF(主要!AG75<>"",主要!AG75,"") | I37: =IF(VLOOKUP(H37,法术大全!$A$3:$E$864,4,0)="√",1,0) -> 0 | J37: =IF(VLOOKUP(H37,法术大全!$A$3:$E$864,5,0)="√",1,0) -> 0 | K37: {=IFERROR(INDEX($H$1:$H$68,SMALL(IF($H$2:$H$68<>"",ROW($H$2:$H$68),4^8),ROW(37:37)))&"","")} | P37: 3 | Q37: 死灵 | R37: 动作或仪式 | S37: 30尺 | T37: 10分钟 | V37: 3 | W37: =RANDBETWEEN(1,6) -> 4 | X37: =RANDBETWEEN(1,8) -> 6 | Y37: =RANDBETWEEN(1,10) -> 6 | Z37: =RANDBETWEEN(1,12) -> 3 | AQ37: > | BE37: /
A38: 37 | B38: =IF(法术书!X39="","",法术书!X39) | C38: =IFERROR(VLOOKUP(B38,法术大全!$A:$W,5,FALSE),"") | D38: =IFERROR(VLOOKUP(B38,法术大全!$A:$W,4,FALSE),"") | E38: 37 | F38: {=IFERROR(INDEX($B$1:$B$301,SMALL(IF($B$1:$B$301<>"",ROW($B$1:$B$301),4^8),ROW(38:38)))&"","")} | H38: =IF(主要!AG76<>"",主要!AG76,"") | I38: =IF(VLOOKUP(H38,法术大全!$A$3:$E$864,4,0)="√",1,0) -> 0 | J38: =IF(VLOOKUP(H38,法术大全!$A$3:$E$864,5,0)="√",1,0) -> 0 | K38: {=IFERROR(INDEX($H$1:$H$68,SMALL(IF($H$2:$H$68<>"",ROW($H$2:$H$68),4^8),ROW(38:38)))&"","")} | P38: 4 | Q38: 预言 | R38: 1分钟或仪式 | S38: 60尺 | T38: 1小时 | V38: 4 | W38: =RANDBETWEEN(1,6) -> 4 | X38: =RANDBETWEEN(1,8) -> 3 | Y38: =RANDBETWEEN(1,10) -> 3 | Z38: =RANDBETWEEN(1,12) -> 12 | AQ38: > | BE38: /
A39: 38 | B39: =IF(法术书!X40="","",法术书!X40) | C39: =IFERROR(VLOOKUP(B39,法术大全!$A:$W,5,FALSE),"") | D39: =IFERROR(VLOOKUP(B39,法术大全!$A:$W,4,FALSE),"") | E39: 38 | F39: {=IFERROR(INDEX($B$1:$B$301,SMALL(IF($B$1:$B$301<>"",ROW($B$1:$B$301),4^8),ROW(39:39)))&"","")} | H39: =IF(主要!AG77<>"",主要!AG77,"") | I39: =IF(VLOOKUP(H39,法术大全!$A$3:$E$864,4,0)="√",1,0) -> 0 | J39: =IF(VLOOKUP(H39,法术大全!$A$3:$E$864,5,0)="√",1,0) -> 0 | K39: {=IFERROR(INDEX($H$1:$H$68,SMALL(IF($H$2:$H$68<>"",ROW($H$2:$H$68),4^8),ROW(39:39)))&"","")} | P39: 5 | Q39: 咒法 | R39: 10分钟 | S39: 90尺 | T39: 8小时 | V39: 5 | W39: =RANDBETWEEN(1,6) -> 5 | X39: =RANDBETWEEN(1,8) -> 8 | Y39: =RANDBETWEEN(1,10) -> 5 | Z39: =RANDBETWEEN(1,12) -> 2 | AL39: 消耗品 | AR39: 稀有度 | AU39: 描述 | BF39: 数量
A40: 39 | B40: =IF(法术书!X41="","",法术书!X41) | C40: =IFERROR(VLOOKUP(B40,法术大全!$A:$W,5,FALSE),"") | D40: =IFERROR(VLOOKUP(B40,法术大全!$A:$W,4,FALSE),"") | E40: 39 | F40: {=IFERROR(INDEX($B$1:$B$301,SMALL(IF($B$1:$B$301<>"",ROW($B$1:$B$301),4^8),ROW(40:40)))&"","")} | H40: =IF(主要!AG78<>"",主要!AG78,"") | I40: =IF(VLOOKUP(H40,法术大全!$A$3:$E$864,4,0)="√",1,0) -> 0 | J40: =IF(VLOOKUP(H40,法术大全!$A$3:$E$864,5,0)="√",1,0) -> 0 | K40: {=IFERROR(INDEX($H$1:$H$68,SMALL(IF($H$2:$H$68<>"",ROW($H$2:$H$68),4^8),ROW(40:40)))&"","")} | P40: 6 | Q40: 惑控 | R40: 1小时 | S40: 120尺 | T40: 24小时 | V40: 6 | W40: =RANDBETWEEN(1,6) -> 2 | X40: =RANDBETWEEN(1,8) -> 4 | Y40: =RANDBETWEEN(1,10) -> 2 | Z40: =RANDBETWEEN(1,12) -> 9 | AQ40: > | BH40: /
...

Sheet 职业
B1: PHB | C1: XGE | D1: TCE | E1: BGG | F1: FTD | G1: VGR | H1: EGtW | K1: UA | L1: TCSR | M1: VSS | N1: HW | Q1: FR:HoF | R1: GH | S1: DoDk | U1: BET | W1: CM | X1: TGS2 | Y1: OTTG | Z1: CBT | AB1: 主职业 | AC1: =IFERROR(IF(VLOOKUP(AB2,$B$3:$Z$22,2,FALSE)=0,"",VLOOKUP(AB2,$B$3:$Z$22,2,FALSE)),"") | AD1: 筛选 | AE1: 兼职1 | AF1: =IFERROR(IF(VLOOKUP(AE2,$B$3:$Z$22,2,FALSE)=0,"",VLOOKUP(AE2,$B$3:$Z$22,2,FALSE)),"") | AG1: 筛选 | AH1: 兼职2 | AI1: =IFERROR(IF(VLOOKUP(AH2,$B$3:$Z$22,2,FALSE)=0,"",VLOOKUP(AH2,$B$3:$Z$22,2,FALSE)),"") | AJ1: 筛选 | AK1: 职业特性 | AL1: =IFERROR(IF(VLOOKUP(AK2,$B$3:$Z$22,2,FALSE)=0,"",VLOOKUP(AK2,$B$3:$Z$22,2,FALSE)),"") | AM1: 筛选 | AO1: 生命值成长 | AQ1: 期望值 | AS1: 生命骰 | AT1: 期望值 | AU1: 1环 | AV1: =IF(AR12+AT17+AX18+AV17=0,"",AR12+AT17+AX18+AV17) | AY1: 职业 | AZ1: 等级 | BA1: 本职 | BB1: 子职 | BC1: 等级 | BE1: 等级 | BF1: 1环 | BG1: 2环 | BH1: 3环 | BI1: 4环 | BJ1: 5环 | BK1: 6环 | BL1: 7环 | BM1: 8环 | BN1: 9环 | BO1: 法术值 | BP1: 等级 | BQ1: 1环 | BR1: 2环 | BS1: 3环 | BT1: 4环 | BU1: 5环 | BV1: 等级 | BW1: 1环 | BX1: 2环 | BY1: 3环 | BZ1: 4环 | CA1: 等级 | CB1: 1环 | CC1: 2环 | CD1: 3环 | CE1: 4环 | CF1: 5环 | CI1: 等级 | CJ1: 名称 | CK1: 描述 | CL1: 最小数据 | CM1: 最大数据 | CO1: 等级 | CP1: 名称 | CQ1: 描述 | CR1: 最小数据行 | CS1: 最大数据行 | CT1: 待选特性 | CV1: 等级 | CW1: 特性名 | CX1: 特性描述
B2: 1 | C2: 2 | D2: 3 | E2: 4 | F2: 5 | G2: 6 | H2: 7 | I2: 8 | J2: 9 | K2: 10 | L2: 11 | M2: 12 | N2: 13 | O2: 14 | P2: 15 | Q2: 16 | R2: 17 | S2: 18 | T2: 19 | U2: 20 | V2: 21 | W2: 22 | X2: 23 | Y2: 24 | Z2: 25 | AB2: =主要!E6 -> 0 | AC2: =IFERROR(IF(VLOOKUP(AB2,$B$3:$Z$22,3,FALSE)=0,"",VLOOKUP(AB2,$B$3:$Z$22,3,FALSE)),"") | AD2: {=IFERROR(INDEX($AC$1:$AC$24,SMALL(IF($AC$1:$AC$24<>"",ROW($AC$1:$AC$24),4^8),ROW(AC1)))&"","")} | AE2: =主要!E7 -> 0 | AF2: =IFERROR(IF(VLOOKUP(AE2,$B$3:$Z$22,3,FALSE)=0,"",VLOOKUP(AE2,$B$3:$Z$22,3,FALSE)),"") | AG2: {=IFERROR(INDEX($AF$1:$AF$24,SMALL(IF($AF$1:$AF$24<>"",ROW($AF$1:$AF$24),4^8),ROW(1:1)))&"","")} | AH2: =主要!E8 -> 0 | AI2: =IFERROR(IF(VLOOKUP(AH2,$B$3:$Z$22,3,FALSE)=0,"",VLOOKUP(AH2,$B$3:$Z$22,3,FALSE)),"") | AJ2: {=IFERROR(INDEX($AI$1:$AI$24,SMALL(IF($AI$1:$AI$24<>"",ROW($AI$1:$AI$24),4^8),ROW(1:1)))&"","")} | AK2: =主要!AW9 -> 0 | AL2: =IFERROR(IF(VLOOKUP(AK2,$B$3:$Z$22,3,FALSE)=0,"",VLOOKUP(AK2,$B$3:$Z$22,3,FALSE)),"") | AM2: {=IFERROR(INDEX($AL$1:$AL$24,SMALL(IF($AL$1:$AL$24<>"",ROW($AL$1:$AL$24),4^8),ROW(1:1)))&"","")} | AO2: 法师 | AP2: D6 | AQ2: D6 | AR2: 4 | AS2: =IFERROR(VLOOKUP(主要!E6,$AO$2:$AP$21,2,FALSE),"") | AT2: =IFERROR(VLOOKUP(AS2,$AQ$2:$AR$5,2,FALSE),0) -> 0 | AU2: 2环 | AV2: =IF(AR13+AT18+AX19+AV18=0,"",AR13+AT18+AX19+AV18) | AY2: 野蛮人 | AZ2: =IFERROR(VLOOKUP(AY2,$BA$2:$BC$4,3,0),0) -> 0 | BA2: =IF(主要!E6="",0,主要!E6) -> 0 | BB2: =IF(主要!I6="",0,主要!I6) -> 0 | BC2: =IF(主要!O6="",0,主要!O6) -> 1 | BE2: 0 | BP2: 0 | BV2: 0 | CA2: 0 | CH2: 野蛮人 | CI2: 1 | CJ2: 2 | CK2: 3 | CL2: 1 | CM2: {=_xlfn.IFS($AZ$2=20,26,$AZ$2>=19,25,$AZ$2>=18,24,$AZ$2>=17,23,$AZ$2>=15,22,$AZ$2>=11,20,$AZ$2>=9,19,$AZ$2>=7,18,$AZ$2>=5,16,$AZ$2>=4,14,$AZ$2>=3,13,$AZ$2=2,11,$AZ$2=1,9,1,0)} -> 0 | CN2: =IF(主要!AW9<>"",主要!AW9,"") | CO2: =IFERROR(VLOOKUP($CN$2,$CH$2:$CM$22,2,FALSE),"") | CP2: =IFERROR(VLOOKUP($CN$2,$CH$2:$CM$22,3,FALSE),"") | CQ2: =IFERROR(VLOOKUP($CN$2,$CH$2:$CM$22,4,FALSE),"") | CR2: =IFERROR(VLOOKUP($CN$2,$CH$2:$CM$22,5,FALSE),"") | CS2: =IFERROR(VLOOKUP($CN$2,$CH$2:$CM$22,6,FALSE),"") | CT2: =IFERROR(IF(OR(CO6="",COUNTIF($CW$2:$CW$81,CO6)),"",CO6),"") | CU2: {=INDEX(CT:CT,SMALL(IF($CT$2:$CT$101<>"",ROW($CT$2:$CT$101),142),ROW(CT1)))&""} | CV2: =IFERROR(VLOOKUP(CW2,$CO$6:$CQ$105,3,FALSE),"") | CW2: =IF(主要!AX11="","",主要!AX11) -> 豁免熟练 | CX2: =IFERROR(VLOOKUP(CW2,$CO$6:$CQ$105,2,FALSE),"")
A3: 1 | B3: 野蛮人 | C3: 狂战士道途 | D3: 兽心道途 | E3: 世界树道途 | F3: 狂热者道途 | G3: =IF(自定义调整栏!$E$3="O","先祖守卫道途","") -> 先祖守卫道途 | H3: =IF(自定义调整栏!$E$3="O","风暴先驱道途","") -> 风暴先驱道途 | I3: =IF(自定义调整栏!$E$4="O","狂野魔法道途","") -> 狂野魔法道途 | J3: =IF(自定义调整栏!$E$4="O","野兽道途","") -> 野兽道途 | K3: =IF(自定义调整栏!$E$7="O","巨人道途","") -> 巨人道途 | L3: =IF(自定义调整栏!$E$26="O","巨像道途","") | M3: =IF(自定义调整栏!$E$34="O","肌肉法师道途","") | R3: =IF(自定义调整栏!$E$27="O","腐鸦道途","") | S3: =IF(自定义调整栏!$E$28="O","古神道途","") | T3: =IF(自定义调整栏!$E$28="O","污霭狂怒者道途","") | U3: =IF(自定义调整栏!$E$30="O","噬影徒","") | W3: =IF(自定义调整栏!$E$35="O","实验道途","") | X3: =IF(自定义调整栏!$E$32="O","炼狱道途","") | Y3: =IF(自定义调整栏!$E$33="O","腹酿道途","") | Z3: =IF(自定义调整栏!$E$36="O","蔑法道途","") | AA3: {=IFERROR(INDEX($B$1:$B$22,SMALL(IF($B$1:$B$22<>"",ROW($B$1:$B$22),4^8),ROW(3:3)))&"","")} -> 野蛮人 | AC3: =IFERROR(IF(VLOOKUP(AB2,$B$3:$Z$22,4,FALSE)=0,"",VLOOKUP(AB2,$B$3:$Z$22,4,FALSE)),"") | AD3: {=IFERROR(INDEX($AC$1:$AC$24,SMALL(IF($AC$1:$AC$24<>"",ROW($AC$1:$AC$24),4^8),ROW(AC2)))&"","")} | AF3: =IFERROR(IF(VLOOKUP(AE2,$B$3:$Z$22,4,FALSE)=0,"",VLOOKUP(AE2,$B$3:$Z$22,4,FALSE)),"") | AG3: {=IFERROR(INDEX($AF$1:$AF$24,SMALL(IF($AF$1:$AF$24<>"",ROW($AF$1:$AF$24),4^8),ROW(2:2)))&"","")} | AI3: =IFERROR(IF(VLOOKUP(AH2,$B$3:$Z$22,4,FALSE)=0,"",VLOOKUP(AH2,$B$3:$Z$22,4,FALSE)),"") | AJ3: {=IFERROR(INDEX($AI$1:$AI$24,SMALL(IF($AI$1:$AI$24<>"",ROW($AI$1:$AI$24),4^8),ROW(2:2)))&"","")} | AL3: =IFERROR(IF(VLOOKUP(AK2,$B$3:$Z$22,4,FALSE)=0,"",VLOOKUP(AK2,$B$3:$Z$22,4,FALSE)),"") | AM3: {=IFERROR(INDEX($AL$1:$AL$24,SMALL(IF($AL$1:$AL$24<>"",ROW($AL$1:$AL$24),4^8),ROW(2:2)))&"","")} | AO3: 术士 | AP3: D6 | AQ3: D8 | AR3: 5 | AS3: =IFERROR(VLOOKUP(主要!E7,$AO$2:$AP$21,2,FALSE),"") | AT3: =IFERROR(VLOOKUP(AS3,$AQ$2:$AR$5,2,FALSE),0) -> 0 | AU3: 3环 | AV3: =IF(AR14+AT19+AX20+AV19=0,"",AR14+AT19+AX20+AV19) | AY3: 吟游诗人 | AZ3: =IFERROR(VLOOKUP(AY3,$BA$2:$BC$4,3,0),0) -> 0 | BA3: =IF(主要!E7="",0,主要!E7) -> 0 | BB3: =IF(主要!I7="",0,主要!I7) -> 0 | BC3: =IF(主要!O7="",0,主要!O7) -> 0 | BE3: 1 | BF3: 2 | BO3: 4 | BP3: 1 | BQ3: 1 | BV3: 1 | CA3: 1 | CB3: 1 | CH3: 吟游诗人 | CI3: 4 | CJ3: 5 | CK3: 6 | CL3: 1 | CM3: {=_xlfn.IFS($AZ$3>=20,24,$AZ$3>=19,23,$AZ$3>=18,22,$AZ$3>=10,21,$AZ$3>=7,20,$AZ$3>=5,19,$AZ$3>=4,18,$AZ$3>=3,17,$AZ$3=2,16,$AZ$3=1,14,1,0)} -> 0 | CN3: =IF(主要!BD9<>"",主要!BD9,"") | CP3: 0v0? | CQ3: 0v0? | CR3: =IFERROR(VLOOKUP($CN$3,$CH$30:$CJ$285,2,FALSE),"") | CS3: =IFERROR(VLOOKUP($CN$3,$CH$30:$CJ$285,3,FALSE),"") | CT3: =IFERROR(IF(OR(CO7="",COUNTIF($CW$2:$CW$81,CO7)),"",CO7),"") | CU3: {=INDEX(CT:CT,SMALL(IF($CT$2:$CT$101<>"",ROW($CT$2:$CT$101),142),ROW(CT2)))&""} | CV3: =IFERROR(VLOOKUP(CW3,$CO$6:$CQ$105,3,FALSE),"") | CW3: =IF(主要!AX12="","",主要!AX12) -> 技能熟练 | CX3: =IFERROR(VLOOKUP(CW3,$CO$6:$CQ$105,2,FALSE),"")
A4: 2 | B4: 吟游诗人 | C4: 舞蹈学院 | D4: 魅心学院 | E4: 逸闻学院 | F4: 勇气学院 | G4: =IF(自定义调整栏!$E$3="O","剑舞学院","") -> 剑舞学院 | H4: =IF(自定义调整栏!$E$3="O","低语学院","") -> 低语学院 | I4: =IF(自定义调整栏!$E$4="O","创造学院","") -> 创造学院 | J4: =IF(自定义调整栏!$E$4="O","雄辩学院","") -> 雄辩学院 | K4: =IF(自定义调整栏!$E$19="O","精魂学院","") -> 精魂学院 | L4: =IF(自定义调整栏!$E$26="O","悲剧学院","") | M4: =IF(自定义调整栏!$E$29="O","旅路学院","") | Q4: =IF(自定义调整栏!$E$10="O","皓月学院","") -> 皓月学院 | R4: =IF(自定义调整栏!$E$27="O","安魂学院","") | S4: =IF(自定义调整栏!$E$28="O","末谕学院","") | U4: =IF(自定义调整栏!$E$30="O","暗影学院","") | W4: =IF(自定义调整栏!$E$35="O","灵哨学院","") | X4: =IF(自定义调整栏!$E$32="O","交易学院","") | Y4: =IF(自定义调整栏!$E$33="O","面具学院","") | Z4: =IF(自定义调整栏!$E$36="O","戏剧学院","") | AA4: {=IFERROR(INDEX($B$1:$B$22,SMALL(IF($B$1:$B$22<>"",ROW($B$1:$B$22),4^8),ROW(4:4)))&"","")} -> 吟游诗人 | AC4: =IFERROR(IF(VLOOKUP(AB2,$B$3:$Z$22,5,FALSE)=0,"",VLOOKUP(AB2,$B$3:$Z$22,5,FALSE)),"") | AD4: {=IFERROR(INDEX($AC$1:$AC$24,SMALL(IF($AC$1:$AC$24<>"",ROW($AC$1:$AC$24),4^8),ROW(AC3)))&"","")} | AF4: =IFERROR(IF(VLOOKUP(AE2,$B$3:$Z$22,5,FALSE)=0,"",VLOOKUP(AE2,$B$3:$Z$22,5,FALSE)),"") | AG4: {=IFERROR(INDEX($AF$1:$AF$24,SMALL(IF($AF$1:$AF$24<>"",ROW($AF$1:$AF$24),4^8),ROW(3:3)))&"","")} | AI4: =IFERROR(IF(VLOOKUP(AH2,$B$3:$Z$22,5,FALSE)=0,"",VLOOKUP(AH2,$B$3:$Z$22,5,FALSE)),"") | AJ4: {=IFERROR(INDEX($AI$1:$AI$24,SMALL(IF($AI$1:$AI$24<>"",ROW($AI$1:$AI$24),4^8),ROW(3:3)))&"","")} | AL4: =IFERROR(IF(VLOOKUP(AK2,$B$3:$Z$22,5,FALSE)=0,"",VLOOKUP(AK2,$B$3:$Z$22,5,FALSE)),"") | AM4: {=IFERROR(INDEX($AL$1:$AL$24,SMALL(IF($AL$1:$AL$24<>"",ROW($AL$1:$AL$24),4^8),ROW(3:3)))&"","")} | AO4: 灵能使 | AP4: D6 | AQ4: D10 | AR4: 6 | AS4: =IFERROR(VLOOKUP(主要!E8,$AO$2:$AP$21,2,FALSE),"") | AT4: =IFERROR(VLOOKUP(AS4,$AQ$2:$AR$5,2,FALSE),0) -> 0 | AU4: 4环 | AV4: =IF(AR15+AT20+AX21+AV20=0,"",AR15+AT20+AX21+AV20) | AY4: 牧师 | AZ4: =IFERROR(VLOOKUP(AY4,$BA$2:$BC$4,3,0),0) -> 0 | BA4: =IF(主要!E8="",0,主要!E8) -> 0 | BB4: =IF(主要!I8="",0,主要!I8) -> 0 | BC4: =IF(主要!O8="",0,主要!O8) -> 0 | BE4: 2 | BF4: 3 | BO4: 6 | BP4: 2 | BQ4: 2 | BV4: 2 | CA4: 2 | CB4: 2 | CH4: 牧师 | CI4: 7 | CJ4: 8 | CK4: 9 | CL4: 1 | CM4: {=_xlfn.IFS($AZ$4>=20,25,$AZ$4>=19,24,$AZ$4>=14,23,$AZ$4>=10,22,$AZ$4>=7,21,$AZ$4>=5,20,$AZ$4>=4,19,$AZ$4>=3,18,$AZ$4=2,17,$AZ$4=1,14,1,0)} -> 0 | CT4: =IFERROR(IF(OR(CO8="",COUNTIF($CW$2:$CW$81,CO8)),"",CO8),"") | CU4: {=INDEX(CT:CT,SMALL(IF($CT$2:$CT$101<>"",ROW($CT$2:$CT$101),142),ROW(CT3)))&""} | CV4: =IFERROR(VLOOKUP(CW4,$CO$6:$CQ$105,3,FALSE),"") | CW4: =IF(主要!AX13="","",主要!AX13) -> 武器熟练 | CX4: =IFERROR(VLOOKUP(CW4,$CO$6:$CQ$105,2,FALSE),"")
A5: 3 | B5: 牧师 | C5: 生命领域 | D5: 光明领域 | E5: 诡术领域 | F5: 战争领域 | G5: =IF(自定义调整栏!$E$3="O","锻造领域","") -> 锻造领域 | H5: =IF(自定义调整栏!$E$3="O","坟墓领域","") -> 坟墓领域 | I5: =IF(自定义调整栏!$E$4="O","秩序领域","") -> 秩序领域 | J5: =IF(自定义调整栏!$E$4="O","和平领域","") -> 和平领域 | K5: =IF(自定义调整栏!$E$4="O","暮光领域","") -> 暮光领域 | L5: =IF(自定义调整栏!$E$26="O","月亮领域","") | M5: =IF(自定义调整栏!$E$26="O","鲜血领域","") | N5: =IF(自定义调整栏!$E$29="O","团队领域","") | O5: =IF(自定义调整栏!$E$29="O","黑夜领域","") | Q5: =IF(自定义调整栏!$E$10="O","知识领域","") -> 知识领域 | R5: =IF(自定义调整栏!$E$27="O","审判领域","") | S5: =IF(自定义调整栏!$E$28="O","暗影领域-德城","") | T5: =IF(自定义调整栏!$E$30="O","监管领域","") | U5: =IF(自定义调整栏!$E$30="O","暗影领域","") | W5: =IF(自定义调整栏!$E$35="O","丰收领域","") | X5: =IF(自定义调整栏!$E$32="O","宴饮领域","") | Z5: =IF(自定义调整栏!$E$36="O","天启领域","") | AA5: {=IFERROR(INDEX($B$1:$B$22,SMALL(IF($B$1:$B$22<>"",ROW($B$1:$B$22),4^8),ROW(5:5)))&"","")} -> 牧师 | AC5: =IFERROR(IF(VLOOKUP(AB2,$B$3:$Z$22,6,FALSE)=0,"",VLOOKUP(AB2,$B$3:$Z$22,6,FALSE)),"") | AD5: {=IFERROR(INDEX($AC$1:$AC$24,SMALL(IF($AC$1:$AC$24<>"",ROW($AC$1:$AC$24),4^8),ROW(AC4)))&"","")} | AF5: =IFERROR(IF(VLOOKUP(AE2,$B$3:$Z$22,6,FALSE)=0,"",VLOOKUP(AE2,$B$3:$Z$22,6,FALSE)),"") | AG5: {=IFERROR(INDEX($AF$1:$AF$24,SMALL(IF($AF$1:$AF$24<>"",ROW($AF$1:$AF$24),4^8),ROW(4:4)))&"","")} | AI5: =IFERROR(IF(VLOOKUP(AH2,$B$3:$Z$22,6,FALSE)=0,"",VLOOKUP(AH2,$B$3:$Z$22,6,FALSE)),"") | AJ5: {=IFERROR(INDEX($AI$1:$AI$24,SMALL(IF($AI$1:$AI$24<>"",ROW($AI$1:$AI$24),4^8),ROW(4:4)))&"","")} | AL5: =IFERROR(IF(VLOOKUP(AK2,$B$3:$Z$22,6,FALSE)=0,"",VLOOKUP(AK2,$B$3:$Z$22,6,FALSE)),"") | AM5: {=IFERROR(INDEX($AL$1:$AL$24,SMALL(IF($AL$1:$AL$24<>"",ROW($AL$1:$AL$24),4^8),ROW(4:4)))&"","")} | AO5: 吟游诗人 | AP5: D8 | AQ5: D12 | AR5: 7 | AU5: 5环 | AV5: =IF(AR16+AT21+AV21=0,"",AR16+AT21+AV21) | AY5: 德鲁伊 | AZ5: =IFERROR(VLOOKUP(AY5,$BA$2:$BC$4,3,0),0) -> 0 | BE5: 3 | BF5: 4 | BG5: 2 | BO5: 14 | BP5: 3 | BR5: 2 | BV5: 3 | BW5: 1 | CA5: 3 | CC5: 2 | CH5: 德鲁伊 | CI5: 10 | CJ5: 11 | CK5: 12 | CL5: 1 | CM5: {=_xlfn.IFS($AZ$5>=20,29,$AZ$5>=19,28,$AZ$5>=18,27,$AZ$5>=15,26,$AZ$5>=7,25,$AZ$5>=5,24,$AZ$5>=4,23,$AZ$5>=3,22,$AZ$5=2,21,$AZ$5=1,15,1,0)} -> 0 | CN5: 0 | CO5: 名称 | CP5: 描述 | CR5: 增值 | CT5: =IFERROR(IF(OR(CO9="",COUNTIF($CW$2:$CW$81,CO9)),"",CO9),"") | CU5: {=INDEX(CT:CT,SMALL(IF($CT$2:$CT$101<>"",ROW($CT$2:$CT$101),142),ROW(CT4)))&""} | CV5: =IFERROR(VLOOKUP(CW5,$CO$6:$CQ$105,3,FALSE),"") | CW5: =IF(主要!AX14="","",主要!AX14) -> 工具熟练 | CX5: =IFERROR(VLOOKUP(CW5,$CO$6:$CQ$105,2,FALSE),"")
A6: 4 | B6: 德鲁伊 | C6: 大地结社 | D6: 月亮结社 | E6: 海洋结社 | F6: 星辰结社 | G6: =IF(自定义调整栏!$E$3="O","梦境结社","") -> 梦境结社 | H6: =IF(自定义调整栏!$E$3="O","牧人结社","") -> 牧人结社 | I6: =IF(自定义调整栏!$E$4="O","孢子结社","") -> 孢子结社 | J6: =IF(自定义调整栏!$E$4="O","野火结社","") -> 野火结社 | K6: =IF(自定义调整栏!$E$26="O","枯朽结社","") | L6: =IF(自定义调整栏!$E$29="O","守望结社","") | O6: =IF(自定义调整栏!$E$39="O","恩护结社","") | S6: =IF(自定义调整栏!$E$28="O","秽染结社","") | U6: =IF(自定义调整栏!$E$30="O","暗影结社","") | V6: =IF(自定义调整栏!$E$35="O","旧途结社","") | W6: =IF(自定义调整栏!$E$35="O","柳艺结社","") | X6: =IF(自定义调整栏!$E$32="O","巨龙结社","") | Y6: =IF(自定义调整栏!$E$33="O","落英结社","") | Z6: =IF(自定义调整栏!$E$36="O","共生结社","") | AA6: {=IFERROR(INDEX($B$1:$B$22,SMALL(IF($B$1:$B$22<>"",ROW($B$1:$B$22),4^8),ROW(6:6)))&"","")} -> 德鲁伊 | AC6: =IFERROR(IF(VLOOKUP(AB2,$B$3:$Z$22,7,FALSE)=0,"",VLOOKUP(AB2,$B$3:$Z$22,7,FALSE)),"") | AD6: {=IFERROR(INDEX($AC$1:$AC$24,SMALL(IF($AC$1:$AC$24<>"",ROW($AC$1:$AC$24),4^8),ROW(AC5)))&"","")} | AF6: =IFERROR(IF(VLOOKUP(AE2,$B$3:$Z$22,7,FALSE)=0,"",VLOOKUP(AE2,$B$3:$Z$22,7,FALSE)),"") | AG6: {=IFERROR(INDEX($AF$1:$AF$24,SMALL(IF($AF$1:$AF$24<>"",ROW($AF$1:$AF$24),4^8),ROW(5:5)))&"","")} | AI6: =IFERROR(IF(VLOOKUP(AH2,$B$3:$Z$22,7,FALSE)=0,"",VLOOKUP(AH2,$B$3:$Z$22,7,FALSE)),"") | AJ6: {=IFERROR(INDEX($AI$1:$AI$24,SMALL(IF($AI$1:$AI$24<>"",ROW($AI$1:$AI$24),4^8),ROW(5:5)))&"","")} | AL6: =IFERROR(IF(VLOOKUP(AK2,$B$3:$Z$22,7,FALSE)=0,"",VLOOKUP(AK2,$B$3:$Z$22,7,FALSE)),"") | AM6: {=IFERROR(INDEX($AL$1:$AL$24,SMALL(IF($AL$1:$AL$24<>"",ROW($AL$1:$AL$24),4^8),ROW(5:5)))&"","")} | AO6: 牧师 | AP6: D8 | AQ6: 首级 | AS6: 总等级 | AT6: =主要!O6+主要!O7+主要!O8 -> 1 | AU6: 6环 | AV6: =IF(AR17+0=0,"",AR17) | AY6: 战士 | AZ6: =IFERROR(VLOOKUP(AY6,$BA$2:$BC$4,3,0),0) -> 0 | BA6: 奥法骑士 | BB6: =IF($BB$2="奥法骑士",$BC$2,IF($BB$3="奥法骑士",$BC$3,IF($BB$4="奥法骑士",$BC$4,0))) -> 0 | BC6: =IF($AT$9=0,IF($AT$10=0,IF(SUM(BB7:BB11)=0,ROUNDUP(BB6/3,0),ROUNDDOWN(BB6/3,0)),ROUNDDOWN(BB6/3,0)),ROUNDDOWN(BB6/3,0)) -> 0 | BE6: 4 | BF6: 4 | BG6: 3 | BO6: 17 | BP6: 4 | BR6: 2 | BV6: 4 | BW6: 1 | CA6: 4 | CC6: 2 | CH6: 战士 | CI6: 13 | CJ6: 14 | CK6: 15 | CL6: 1 | CM6: {=_xlfn.IFS($AZ$6=20,21,$AZ$6>=19,20,$AZ$6>=13,19,$AZ$6>=11,18,$AZ$6>=9,17,$AZ$6>=5,15,$AZ$6>=4,13,$AZ$6>=3,12,$AZ$6>=2,11,$AZ$6=1,9,1,0)} -> 0 | CN6: =IFERROR(IF(CN5+1>CS2,IF(CN5+1>CS2,IF(CR3+CR5>CS3,"",CR3+CR5)),CN5+1),"") -> 1 | CO6: {=IFERROR(INDEX($B$34:$BO$262,CN6,$CP$2),"")} | CP6: {=IFERROR(INDEX($B$34:$BO$262,CN6,$CQ$2),"")} | CQ6: {=IF(IFERROR(INDEX($B$34:$BO$262,CN6,$CO$2),"")=0,"",IFERROR(INDEX($B$34:$BO$262,CN6,$CO$2),""))} | CR6: =IFERROR(IF(CN5+1>CS2,CR5+1,0),"") -> 0 | CT6: =IFERROR(IF(OR(CO10="",COUNTIF($CW$2:$CW$81,CO10)),"",CO10),"") | CU6: {=INDEX(CT:CT,SMALL(IF($CT$2:$CT$101<>"",ROW($CT$2:$CT$101),142),ROW(CT5)))&""} | CV6: =IFERROR(VLOOKUP(CW6,$CO$6:$CQ$105,3,FALSE),"") | CW6: =IF(主要!AX15="","",主要!AX15) -> 护甲受训 | CX6: =IFERROR(VLOOKUP(CW6,$CO$6:$CQ$105,2,FALSE),"")
A7: 5 | B7: 战士 | C7: 战斗大师 | D7: 勇士 | E7: 奥法骑士 | F7: 灵能武士 | G7: =IF(自定义调整栏!$E$3="O","魔射手","") -> 魔射手 | H7: =IF(自定义调整栏!$E$3="O","骑兵","") -> 骑兵 | I7: =IF(自定义调整栏!$E$3="O","武士","") -> 武士 | J7: =IF(自定义调整栏!$E$4="O","符文骑士","") -> 符文骑士 | K7: =IF(自定义调整栏!$E$23="O","回音骑士","") -> 回音骑士 | L7: =IF(自定义调整栏!$E$34="O","地城探险家","") | M7: =IF(自定义调整栏!$E$29="O","法外狂徒","") | O7: =IF(自定义调整栏!$E$39="O","角斗士","") | Q7: =IF(自定义调整栏!$E$10="O","旗将","") -> 旗将 | R7: =IF(自定义调整栏!$E$27="O","破锋者","") | S7: =IF(自定义调整栏!$E$28="O","指挥官","") | W7: =IF(自定义调整栏!$E$35="O","陵墓守卫","") | X7: =IF(自定义调整栏!$E$32="O","钢隼","") | Y7: =IF(自定义调整栏!$E$33="O","附灵","") | Z7: =IF(自定义调整栏!$E$36="O","英雄","") | AA7: {=IFERROR(INDEX($B$1:$B$22,SMALL(IF($B$1:$B$22<>"",ROW($B$1:$B$22),4^8),ROW(7:7)))&"","")} -> 战士 | AC7: =IFERROR(IF(VLOOKUP(AB2,$B$3:$Z$22,8,FALSE)=0,"",VLOOKUP(AB2,$B$3:$Z$22,8,FALSE)),"") | AD7: {=IFERROR(INDEX($AC$1:$AC$24,SMALL(IF($AC$1:$AC$24<>"",ROW($AC$1:$AC$24),4^8),ROW(AC6)))&"","")} | AF7: =IFERROR(IF(VLOOKUP(AE2,$B$3:$Z$22,8,FALSE)=0,"",VLOOKUP(AE2,$B$3:$Z$22,8,FALSE)),"") | AG7: {=IFERROR(INDEX($AF$1:$AF$24,SMALL(IF($AF$1:$AF$24<>"",ROW($AF$1:$AF$24),4^8),ROW(6:6)))&"","")} | AI7: =IFERROR(IF(VLOOKUP(AH2,$B$3:$Z$22,8,FALSE)=0,"",VLOOKUP(AH2,$B$3:$Z$22,8,FALSE)),"") | AJ7: {=IFERROR(INDEX($AI$1:$AI$24,SMALL(IF($AI$1:$AI$24<>"",ROW($AI$1:$AI$24),4^8),ROW(6:6)))&"","")} | AL7: =IFERROR(IF(VLOOKUP(AK2,$B$3:$Z$22,8,FALSE)=0,"",VLOOKUP(AK2,$B$3:$Z$22,8,FALSE)),"") | AM7: {=IFERROR(INDEX($AL$1:$AL$24,SMALL(IF($AL$1:$AL$24<>"",ROW($AL$1:$AL$24),4^8),ROW(6:6)))&"","")} | AO7: 德鲁伊 | AP7: D8 | AQ7: D6 | AR7: 2 | AS7: 首级 | AT7: =IFERROR(VLOOKUP(AS2,AQ7:AR10,2,FALSE),0) -> 0 | AU7: 7环 | AV7: =IF(AR18+0=0,"",AR18) | AY7: 武僧 | AZ7: =IFERROR(VLOOKUP(AY7,$BA$2:$BC$4,3,0),0) -> 0 | BA7: 诡术师 | BB7: =IF($BB$2="诡术师",$BC$2,IF($BB$3="诡术师",$BC$3,IF($BB$4="诡术师",$BC$4,0))) -> 0 | BC7: =IF($AT$9=0,IF($AT$10=0,IF(SUM(BB6,BB8:BB11)=0,ROUNDUP(BB7/3,0),ROUNDDOWN(BB7/3,0)),ROUNDDOWN(BB7/3,0)),ROUNDDOWN(BB7/3,0)) -> 0 | BE7: 5 | BF7: 4 | BG7: 3 | BH7: 2 | BO7: 27 | BP7: 5 | BS7: 2 | BV7: 5 | BW7: 1 | CA7: 5 | CD7: 3 | CH7: 武僧 | CI7: 16 | CJ7: 17 | CK7: 18 | CL7: 1 | CM7: {=_xlfn.IFS($AZ$7=20,28,$AZ$7=19,27,$AZ$7=18,26,$AZ$7>=15,25,$AZ$7>=14,24,$AZ$7>=13,23,$AZ$7>=10,22,$AZ$7>=9,20,$AZ$7>=7,19,$AZ$7>=6,18,$AZ$7>=5,17,$AZ$7>=4,15,$AZ$7>=3,13,$AZ$7=2,11,$AZ$7=1,8,1,0)} -> 0 | CN7: =IFERROR(IF(CN6+1>CS2,IF(CN6+1>CS2,IF(CR3+CR6>CS3,"",CR3+CR6)),CN6+1),"") -> 2 | CO7: {=IFERROR(INDEX($B$34:$BO$262,CN7,$CP$2),"")} | CP7: {=IFERROR(INDEX($B$34:$BO$262,CN7,$CQ$2),"")} | CQ7: {=IF(IFERROR(INDEX($B$34:$BO$262,CN7,$CO$2),"")=0,"",IFERROR(INDEX($B$34:$BO$262,CN7,$CO$2),""))} | CR7: =IFERROR(IF(CN6+1>CS2,CR6+1,0),"") -> 0 | CT7: =IFERROR(IF(OR(CO11="",COUNTIF($CW$2:$CW$81,CO11)),"",CO11),"") | CU7: {=INDEX(CT:CT,SMALL(IF($CT$2:$CT$101<>"",ROW($CT$2:$CT$101),142),ROW(CT6)))&""} | CV7: =IFERROR(VLOOKUP(CW7,$CO$6:$CQ$105,3,FALSE),"") | CW7: =IF(主要!AX16="","",主要!AX16) -> 起始装备 | CX7: =IFERROR(VLOOKUP(CW7,$CO$6:$CQ$105,2,FALSE),"")
A8: 6 | B8: 武僧 | C8: 命流武者 | D8: 暗影武者 | E8: 四象武者 | F8: 散打武者 | G8: =IF(自定义调整栏!$E$3="O","醉拳宗","") -> 醉拳宗 | H8: =IF(自定义调整栏!$E$3="O","剑圣宗","") -> 剑圣宗 | I8: =IF(自定义调整栏!$E$3="O","日魂宗","") -> 日魂宗 | J8: =IF(自定义调整栏!$E$4="O","星我宗","") -> 星我宗 | K8: =IF(自定义调整栏!$E$6="O","神龙宗","") -> 神龙宗 | L8: =IF(自定义调整栏!$E$26="O","钴魂宗","") | M8: =IF(自定义调整栏!$E$34="O","街霸武者","") | O8: =IF(自定义调整栏!$E$40="O","秘术武者","") | S8: =IF(自定义调整栏!$E$28="O","盘蛇宗","") | T8: =IF(自定义调整栏!$E$28="O","织法宗","") | U8: =IF(自定义调整栏!$E$30="O","先知宗","") | W8: =IF(自定义调整栏!$E$35="O","疫瘴武者","") | X8: =IF(自定义调整栏!$E$32="O","虚灵宗","") | Y8: =IF(自定义调整栏!$E$33="O","绵龙牧者","") | Z8: =IF(自定义调整栏!$E$36="O","天衡武者","") | AA8: {=IFERROR(INDEX($B$1:$B$22,SMALL(IF($B$1:$B$22<>"",ROW($B$1:$B$22),4^8),ROW(8:8)))&"","")} -> 武僧 | AC8: =IFERROR(IF(VLOOKUP(AB2,$B$3:$Z$22,9,FALSE)=0,"",VLOOKUP(AB2,$B$3:$Z$22,9,FALSE)),"") | AD8: {=IFERROR(INDEX($AC$1:$AC$24,SMALL(IF($AC$1:$AC$24<>"",ROW($AC$1:$AC$24),4^8),ROW(AC7)))&"","")} | AF8: =IFERROR(IF(VLOOKUP(AE2,$B$3:$Z$22,9,FALSE)=0,"",VLOOKUP(AE2,$B$3:$Z$22,9,FALSE)),"") | AG8: {=IFERROR(INDEX($AF$1:$AF$24,SMALL(IF($AF$1:$AF$24<>"",ROW($AF$1:$AF$24),4^8),ROW(7:7)))&"","")} | AI8: =IFERROR(IF(VLOOKUP(AH2,$B$3:$Z$22,9,FALSE)=0,"",VLOOKUP(AH2,$B$3:$Z$22,9,FALSE)),"") | AJ8: {=IFERROR(INDEX($AI$1:$AI$24,SMALL(IF($AI$1:$AI$24<>"",ROW($AI$1:$AI$24),4^8),ROW(7:7)))&"","")} | AL8: =IFERROR(IF(VLOOKUP(AK2,$B$3:$Z$22,9,FALSE)=0,"",VLOOKUP(AK2,$B$3:$Z$22,9,FALSE)),"") | AM8: {=IFERROR(INDEX($AL$1:$AL$24,SMALL(IF($AL$1:$AL$24<>"",ROW($AL$1:$AL$24),4^8),ROW(7:7)))&"","")} | AO8: 武僧 | AP8: D8 | AQ8: D8 | AR8: 3 | AU8: 8环 | AV8: =IF(AR19+0=0,"",AR19) | AY8: 圣武士 | AZ8: =IFERROR(VLOOKUP(AY8,$BA$2:$BC$4,3,0),0) -> 0 | BA8: 筑灭师 | BB8: =IF($BB$3="筑灭师",$BC$3,IF($BB$4="筑灭师",$BC$4,IF($BB$5="筑灭师",$BC$5,0))) -> 0 | BC8: =IF($AT$9=0,IF($AT$10=0,IF(SUM(BB6:BB7,BB9:BB11)=0,ROUNDUP(BB8/3,0),ROUNDDOWN(BB8/3,0)),ROUNDDOWN(BB8/3,0)),ROUNDDOWN(BB8/3,0)) -> 0 | BE8: 6 | BF8: 4 | BG8: 3 | BH8: 3 | BO8: 32 | BP8: 6 | BS8: 2 | BV8: 6 | BW8: 2 | CA8: 6 | CD8: 3 | CH8: 圣武士 | CI8: 19 | CJ8: 20 | CK8: 21 | CL8: 1 | CM8: {=_xlfn.IFS($AZ$8>=19,29,$AZ$8>=18,28,$AZ$8>=14,27,$AZ$8>=11,26,$AZ$8>=10,25,$AZ$8>=9,24,$AZ$8>=6,23,$AZ$8>=5,22,$AZ$8>=4,20,$AZ$8>=3,19,$AZ$8=2,16,$AZ$8=1,14,1,0)} -> 0 | CN8: =IFERROR(IF(CN7+1>CS2,IF(CN7+1>CS2,IF(CR3+CR7>CS3,"",CR3+CR7)),CN7+1),"") -> 3 | CO8: {=IFERROR(INDEX($B$34:$BO$262,CN8,$CP$2),"")} | CP8: {=IFERROR(INDEX($B$34:$BO$262,CN8,$CQ$2),"")} | CQ8: {=IF(IFERROR(INDEX($B$34:$BO$262,CN8,$CO$2),"")=0,"",IFERROR(INDEX($B$34:$BO$262,CN8,$CO$2),""))} | CR8: =IFERROR(IF(CN7+1>CS2,CR7+1,0),"") -> 0 | CT8: =IFERROR(IF(OR(CO12="",COUNTIF($CW$2:$CW$81,CO12)),"",CO12),"") | CU8: {=INDEX(CT:CT,SMALL(IF($CT$2:$CT$101<>"",ROW($CT$2:$CT$101),142),ROW(CT7)))&""} | CV8: =IFERROR(VLOOKUP(CW8,$CO$6:$CQ$105,3,FALSE),"") | CW8: =IF(主要!AX17="","",主要!AX17) | CX8: =IFERROR(VLOOKUP(CW8,$CO$6:$CQ$105,2,FALSE),"")
